/*
*** MADE BY MRPONYCAPTAIN'S .SCHEMATIC TO .JAVA CONVERTING TOOL v2.0 ***
*/

package com.Testmod.Dungeon.Parts;

import java.util.Random;

import com.Testmod.World.worldGenTestBlock;

import net.minecraft.block.Block;
import net.minecraft.block.BlockStairs;
import net.minecraft.init.Blocks;
import net.minecraft.util.BlockPos;
import net.minecraft.util.EnumFacing;
import net.minecraft.world.World;
import net.minecraft.world.chunk.IChunkProvider;
import net.minecraft.world.gen.feature.WorldGenerator;
import net.minecraftforge.fml.common.IWorldGenerator;

public class EntrancePart
{
	//creating entrance 
	public static boolean generateBuilding(worldGenTestBlock WorldGen, World world, Random rand, int i, int k,int j ,int facing) {
		
		switch (facing) {
		default:
			northGen( WorldGen,world,rand,i, k, j);
			break;			
		}
		
		
	
		
		return true;
	}

	private static void northGen(worldGenTestBlock worldGen, World world, Random rand, int i, int k,int j) {
		worldGen.setBlock(world, i + 0, j + 0, k + 0, Blocks.bedrock, 0);
		worldGen.setBlock(world, i + 0, j + 0, k + 1, Blocks.bedrock, 0);
		worldGen.setBlock(world, i + 0, j + 0, k + 2, Blocks.bedrock, 0);
		worldGen.setBlock(world, i + 0, j + 0, k + 3, Blocks.bedrock, 0);
		worldGen.setBlock(world, i + 0, j + 0, k + 4, Blocks.bedrock, 0);
		worldGen.setBlock(world, i + 0, j + 0, k + 5, Blocks.bedrock, 0);
		worldGen.setBlock(world, i + 0, j + 0, k + 6, Blocks.bedrock, 0);
		worldGen.setBlock(world, i + 0, j + 0, k + 7, Blocks.bedrock, 0);
		worldGen.setBlock(world, i + 0, j + 0, k + 8, Blocks.bedrock, 0);
		worldGen.setBlock(world, i + 0, j + 0, k + 9, Blocks.bedrock, 0);
		worldGen.setBlock(world, i + 0, j + 0, k + 10, Blocks.bedrock, 0);
		worldGen.setBlock(world, i + 0, j + 1, k + 0, Blocks.bedrock, 0);
		worldGen.setBlock(world, i + 0, j + 1, k + 1, Blocks.bedrock, 0);
		worldGen.setBlock(world, i + 0, j + 1, k + 2, Blocks.bedrock, 0);
		worldGen.setBlock(world, i + 0, j + 1, k + 3, Blocks.bedrock, 0);
		worldGen.setBlock(world, i + 0, j + 1, k + 4, Blocks.bedrock, 0);
		worldGen.setBlock(world, i + 0, j + 1, k + 5, Blocks.bedrock, 0);
		worldGen.setBlock(world, i + 0, j + 1, k + 6, Blocks.bedrock, 0);
		worldGen.setBlock(world, i + 0, j + 1, k + 7, Blocks.bedrock, 0);
		worldGen.setBlock(world, i + 0, j + 1, k + 8, Blocks.bedrock, 0);
		worldGen.setBlock(world, i + 0, j + 1, k + 9, Blocks.bedrock, 0);
		worldGen.setBlock(world, i + 0, j + 1, k + 10, Blocks.bedrock, 0);
		worldGen.setBlock(world, i + 0, j + 2, k + 0, Blocks.bedrock, 0);
		worldGen.setBlock(world, i + 0, j + 2, k + 1, Blocks.bedrock, 0);
		worldGen.setBlock(world, i + 0, j + 2, k + 2, Blocks.bedrock, 0);
		worldGen.setBlock(world, i + 0, j + 2, k + 3, Blocks.bedrock, 0);
		worldGen.setBlock(world, i + 0, j + 2, k + 4, Blocks.bedrock, 0);
		worldGen.setBlock(world, i + 0, j + 2, k + 5, Blocks.bedrock, 0);
		worldGen.setBlock(world, i + 0, j + 2, k + 6, Blocks.bedrock, 0);
		worldGen.setBlock(world, i + 0, j + 2, k + 7, Blocks.bedrock, 0);
		worldGen.setBlock(world, i + 0, j + 2, k + 8, Blocks.bedrock, 0);
		worldGen.setBlock(world, i + 0, j + 2, k + 9, Blocks.bedrock, 0);
		worldGen.setBlock(world, i + 0, j + 2, k + 10, Blocks.bedrock, 0);
		worldGen.setBlock(world, i + 0, j + 3, k + 0, Blocks.bedrock, 0);
		worldGen.setBlock(world, i + 0, j + 3, k + 1, Blocks.bedrock, 0);
		worldGen.setBlock(world, i + 0, j + 3, k + 2, Blocks.bedrock, 0);
		worldGen.setBlock(world, i + 0, j + 3, k + 3, Blocks.bedrock, 0);
		worldGen.setBlock(world, i + 0, j + 3, k + 4, Blocks.bedrock, 0);
		worldGen.setBlock(world, i + 0, j + 3, k + 5, Blocks.bedrock, 0);
		worldGen.setBlock(world, i + 0, j + 3, k + 6, Blocks.bedrock, 0);
		worldGen.setBlock(world, i + 0, j + 3, k + 7, Blocks.bedrock, 0);
		worldGen.setBlock(world, i + 0, j + 3, k + 8, Blocks.bedrock, 0);
		worldGen.setBlock(world, i + 0, j + 3, k + 9, Blocks.bedrock, 0);
		worldGen.setBlock(world, i + 0, j + 3, k + 10, Blocks.bedrock, 0);
		worldGen.setBlock(world, i + 0, j + 4, k + 0, Blocks.bedrock, 0);
		worldGen.setBlock(world, i + 0, j + 4, k + 1, Blocks.bedrock, 0);
		worldGen.setBlock(world, i + 0, j + 4, k + 2, Blocks.bedrock, 0);
		worldGen.setBlock(world, i + 0, j + 4, k + 3, Blocks.bedrock, 0);
		worldGen.setBlock(world, i + 0, j + 4, k + 4, Blocks.bedrock, 0);
		worldGen.setBlock(world, i + 0, j + 4, k + 5, Blocks.bedrock, 0);
		worldGen.setBlock(world, i + 0, j + 4, k + 6, Blocks.bedrock, 0);
		worldGen.setBlock(world, i + 0, j + 4, k + 7, Blocks.bedrock, 0);
		worldGen.setBlock(world, i + 0, j + 4, k + 8, Blocks.bedrock, 0);
		worldGen.setBlock(world, i + 0, j + 4, k + 9, Blocks.bedrock, 0);
		worldGen.setBlock(world, i + 0, j + 4, k + 10, Blocks.bedrock, 0);
		worldGen.setBlock(world, i + 0, j + 5, k + 0, Blocks.bedrock, 0);
		worldGen.setBlock(world, i + 0, j + 5, k + 1, Blocks.bedrock, 0);
		worldGen.setBlock(world, i + 0, j + 5, k + 2, Blocks.bedrock, 0);
		worldGen.setBlock(world, i + 0, j + 5, k + 3, Blocks.bedrock, 0);
		worldGen.setBlock(world, i + 0, j + 5, k + 4, Blocks.bedrock, 0);
		worldGen.setBlock(world, i + 0, j + 5, k + 5, Blocks.bedrock, 0);
		worldGen.setBlock(world, i + 0, j + 5, k + 6, Blocks.bedrock, 0);
		worldGen.setBlock(world, i + 0, j + 5, k + 7, Blocks.bedrock, 0);
		worldGen.setBlock(world, i + 0, j + 5, k + 8, Blocks.bedrock, 0);
		worldGen.setBlock(world, i + 0, j + 5, k + 9, Blocks.bedrock, 0);
		worldGen.setBlock(world, i + 0, j + 5, k + 10, Blocks.bedrock, 0);
		worldGen.setBlock(world, i + 0, j + 6, k + 0, Blocks.bedrock, 0);
		worldGen.setBlock(world, i + 0, j + 6, k + 1, Blocks.bedrock, 0);
		worldGen.setBlock(world, i + 0, j + 6, k + 2, Blocks.bedrock, 0);
		worldGen.setBlock(world, i + 0, j + 6, k + 3, Blocks.bedrock, 0);
		worldGen.setBlock(world, i + 0, j + 6, k + 4, Blocks.bedrock, 0);
		worldGen.setBlock(world, i + 0, j + 6, k + 5, Blocks.bedrock, 0);
		worldGen.setBlock(world, i + 0, j + 6, k + 6, Blocks.bedrock, 0);
		worldGen.setBlock(world, i + 0, j + 6, k + 7, Blocks.bedrock, 0);
		worldGen.setBlock(world, i + 0, j + 6, k + 8, Blocks.bedrock, 0);
		worldGen.setBlock(world, i + 0, j + 6, k + 9, Blocks.bedrock, 0);
		worldGen.setBlock(world, i + 0, j + 6, k + 10, Blocks.bedrock, 0);
		worldGen.setBlock(world, i + 0, j + 7, k + 0, Blocks.bedrock, 0);
		worldGen.setBlock(world, i + 0, j + 7, k + 1, Blocks.bedrock, 0);
		worldGen.setBlock(world, i + 0, j + 7, k + 2, Blocks.bedrock, 0);
		worldGen.setBlock(world, i + 0, j + 7, k + 3, Blocks.bedrock, 0);
		worldGen.setBlock(world, i + 0, j + 7, k + 4, Blocks.bedrock, 0);
		worldGen.setBlock(world, i + 0, j + 7, k + 5, Blocks.bedrock, 0);
		worldGen.setBlock(world, i + 0, j + 7, k + 6, Blocks.bedrock, 0);
		worldGen.setBlock(world, i + 0, j + 7, k + 7, Blocks.bedrock, 0);
		worldGen.setBlock(world, i + 0, j + 7, k + 8, Blocks.bedrock, 0);
		worldGen.setBlock(world, i + 0, j + 7, k + 9, Blocks.bedrock, 0);
		worldGen.setBlock(world, i + 0, j + 7, k + 10, Blocks.bedrock, 0);
		worldGen.setBlock(world, i + 0, j + 8, k + 0, Blocks.bedrock, 0);
		worldGen.setBlock(world, i + 0, j + 8, k + 1, Blocks.bedrock, 0);
		worldGen.setBlock(world, i + 0, j + 8, k + 2, Blocks.bedrock, 0);
		worldGen.setBlock(world, i + 0, j + 8, k + 3, Blocks.bedrock, 0);
		worldGen.setBlock(world, i + 0, j + 8, k + 4, Blocks.bedrock, 0);
		worldGen.setBlock(world, i + 0, j + 8, k + 5, Blocks.bedrock, 0);
		worldGen.setBlock(world, i + 0, j + 8, k + 6, Blocks.bedrock, 0);
		worldGen.setBlock(world, i + 0, j + 8, k + 7, Blocks.bedrock, 0);
		worldGen.setBlock(world, i + 0, j + 8, k + 8, Blocks.bedrock, 0);
		worldGen.setBlock(world, i + 0, j + 8, k + 9, Blocks.bedrock, 0);
		worldGen.setBlock(world, i + 0, j + 8, k + 10, Blocks.bedrock, 0);
		worldGen.setBlock(world, i + 0, j + 9, k + 0, Blocks.bedrock, 0);
		worldGen.setBlock(world, i + 0, j + 9, k + 1, Blocks.bedrock, 0);
		worldGen.setBlock(world, i + 0, j + 9, k + 2, Blocks.bedrock, 0);
		worldGen.setBlock(world, i + 0, j + 9, k + 3, Blocks.bedrock, 0);
		worldGen.setBlock(world, i + 0, j + 9, k + 4, Blocks.bedrock, 0);
		worldGen.setBlock(world, i + 0, j + 9, k + 5, Blocks.bedrock, 0);
		worldGen.setBlock(world, i + 0, j + 9, k + 6, Blocks.bedrock, 0);
		worldGen.setBlock(world, i + 0, j + 9, k + 7, Blocks.bedrock, 0);
		worldGen.setBlock(world, i + 0, j + 9, k + 8, Blocks.bedrock, 0);
		worldGen.setBlock(world, i + 0, j + 9, k + 9, Blocks.bedrock, 0);
		worldGen.setBlock(world, i + 0, j + 9, k + 10, Blocks.bedrock, 0);
		worldGen.setBlock(world, i + 0, j + 10, k + 0, Blocks.bedrock, 0);
		worldGen.setBlock(world, i + 0, j + 10, k + 1, Blocks.bedrock, 0);
		worldGen.setBlock(world, i + 0, j + 10, k + 2, Blocks.bedrock, 0);
		worldGen.setBlock(world, i + 0, j + 10, k + 3, Blocks.bedrock, 0);
		worldGen.setBlock(world, i + 0, j + 10, k + 4, Blocks.bedrock, 0);
		worldGen.setBlock(world, i + 0, j + 10, k + 5, Blocks.bedrock, 0);
		worldGen.setBlock(world, i + 0, j + 10, k + 6, Blocks.bedrock, 0);
		worldGen.setBlock(world, i + 0, j + 10, k + 7, Blocks.bedrock, 0);
		worldGen.setBlock(world, i + 0, j + 10, k + 8, Blocks.bedrock, 0);
		worldGen.setBlock(world, i + 0, j + 10, k + 9, Blocks.bedrock, 0);
		worldGen.setBlock(world, i + 0, j + 10, k + 10, Blocks.bedrock, 0);
		worldGen.setBlock(world, i + 1, j + 0, k + 0, Blocks.bedrock, 0);
		worldGen.setBlock(world, i + 1, j + 0, k + 1, Blocks.bedrock, 0);
		worldGen.setBlock(world, i + 1, j + 0, k + 2, Blocks.bedrock, 0);
		worldGen.setBlock(world, i + 1, j + 0, k + 3, Blocks.bedrock, 0);
		worldGen.setBlock(world, i + 1, j + 0, k + 4, Blocks.bedrock, 0);
		worldGen.setBlock(world, i + 1, j + 0, k + 5, Blocks.bedrock, 0);
		worldGen.setBlock(world, i + 1, j + 0, k + 6, Blocks.bedrock, 0);
		worldGen.setBlock(world, i + 1, j + 0, k + 7, Blocks.bedrock, 0);
		worldGen.setBlock(world, i + 1, j + 0, k + 8, Blocks.bedrock, 0);
		worldGen.setBlock(world, i + 1, j + 0, k + 9, Blocks.bedrock, 0);
		worldGen.setBlock(world, i + 1, j + 0, k + 10, Blocks.bedrock, 0);
		worldGen.setBlock(world, i + 1, j + 1, k + 0, Blocks.bedrock, 0);
		worldGen.setBlock(world, i + 1, j + 1, k + 1, Blocks.stonebrick, 0);
		worldGen.setBlock(world, i + 1, j + 1, k + 2, Blocks.stonebrick, 0);
		worldGen.setBlock(world, i + 1, j + 1, k + 3, Blocks.stonebrick, 0);
		worldGen.setBlock(world, i + 1, j + 1, k + 4, Blocks.stonebrick, 0);
		worldGen.setBlock(world, i + 1, j + 1, k + 5, Blocks.stonebrick, 0);
		worldGen.setBlock(world, i + 1, j + 1, k + 6, Blocks.stonebrick, 0);
		worldGen.setBlock(world, i + 1, j + 1, k + 7, Blocks.stonebrick, 0);
		worldGen.setBlock(world, i + 1, j + 1, k + 8, Blocks.stonebrick, 0);
		worldGen.setBlock(world, i + 1, j + 1, k + 9, Blocks.stonebrick, 0);
		worldGen.setBlock(world, i + 1, j + 1, k + 10, Blocks.bedrock, 0);
		worldGen.setBlock(world, i + 1, j + 2, k + 0, Blocks.bedrock, 0);
		worldGen.setBlock(world, i + 1, j + 2, k + 1, Blocks.stonebrick, 0);
		worldGen.setBlock(world, i + 1, j + 2, k + 2, Blocks.cobblestone, 0);
		worldGen.setBlock(world, i + 1, j + 2, k + 3, Blocks.stonebrick, 0);
		worldGen.setBlock(world, i + 1, j + 2, k + 4, Blocks.stonebrick, 0);
		worldGen.setBlock(world, i + 1, j + 2, k + 5, Blocks.stonebrick, 0);
		worldGen.setBlock(world, i + 1, j + 2, k + 6, Blocks.stonebrick, 0);
		worldGen.setBlock(world, i + 1, j + 2, k + 7, Blocks.stonebrick, 0);
		worldGen.setBlock(world, i + 1, j + 2, k + 8, Blocks.stonebrick, 0);
		worldGen.setBlock(world, i + 1, j + 2, k + 9, Blocks.stonebrick, 0);
		worldGen.setBlock(world, i + 1, j + 2, k + 10, Blocks.bedrock, 0);
		worldGen.setBlock(world, i + 1, j + 3, k + 0, Blocks.bedrock, 0);
		worldGen.setBlock(world, i + 1, j + 3, k + 1, Blocks.stonebrick, 0);
		worldGen.setBlock(world, i + 1, j + 3, k + 2, Blocks.stonebrick, 0);
		worldGen.setBlock(world, i + 1, j + 3, k + 3, Blocks.stonebrick, 0);
		worldGen.setBlock(world, i + 1, j + 3, k + 4, Blocks.stonebrick, 0);
		worldGen.setBlock(world, i + 1, j + 3, k + 5, Blocks.stonebrick, 0);
		worldGen.setBlock(world, i + 1, j + 3, k + 6, Blocks.stonebrick, 0);
		worldGen.setBlock(world, i + 1, j + 3, k + 7, Blocks.stonebrick, 0);
		worldGen.setBlock(world, i + 1, j + 3, k + 8, Blocks.stonebrick, 0);
		worldGen.setBlock(world, i + 1, j + 3, k + 9, Blocks.stonebrick, 0);
		worldGen.setBlock(world, i + 1, j + 3, k + 10, Blocks.bedrock, 0);
		worldGen.setBlock(world, i + 1, j + 4, k + 0, Blocks.bedrock, 0);
		worldGen.setBlock(world, i + 1, j + 4, k + 1, Blocks.stonebrick, 0);
		worldGen.setBlock(world, i + 1, j + 4, k + 2, Blocks.stonebrick, 0);
		worldGen.setBlock(world, i + 1, j + 4, k + 3, Blocks.stone_slab, 5);
		worldGen.setBlock(world, i + 1, j + 4, k + 4, Blocks.stonebrick, 0);
		worldGen.setBlock(world, i + 1, j + 4, k + 5, Blocks.stonebrick, 0);
		worldGen.setBlock(world, i + 1, j + 4, k + 6, Blocks.stonebrick, 0);
		worldGen.setBlock(world, i + 1, j + 4, k + 7, Blocks.stonebrick, 0);
		worldGen.setBlock(world, i + 1, j + 4, k + 8, Blocks.stonebrick, 0);
		worldGen.setBlock(world, i + 1, j + 4, k + 9, Blocks.stonebrick, 0);
		worldGen.setBlock(world, i + 1, j + 4, k + 10, Blocks.bedrock, 0);
		worldGen.setBlock(world, i + 1, j + 5, k + 0, Blocks.bedrock, 0);
		worldGen.setBlock(world, i + 1, j + 5, k + 1, Blocks.stonebrick, 0);
		worldGen.setBlock(world, i + 1, j + 5, k + 2, Blocks.stonebrick, 0);
		worldGen.setBlock(world, i + 1, j + 5, k + 3, Blocks.stonebrick, 0);
		worldGen.setBlock(world, i + 1, j + 5, k + 4, Blocks.stonebrick, 0);
		worldGen.setBlock(world, i + 1, j + 5, k + 5, Blocks.stonebrick, 0);
		worldGen.setBlock(world, i + 1, j + 5, k + 6, Blocks.stonebrick, 0);
		worldGen.setBlock(world, i + 1, j + 5, k + 7, Blocks.stonebrick, 0);
		worldGen.setBlock(world, i + 1, j + 5, k + 8, Blocks.stonebrick, 0);
		worldGen.setBlock(world, i + 1, j + 5, k + 9, Blocks.stonebrick, 0);
		worldGen.setBlock(world, i + 1, j + 5, k + 10, Blocks.bedrock, 0);
		worldGen.setBlock(world, i + 1, j + 6, k + 0, Blocks.bedrock, 0);
		worldGen.setBlock(world, i + 1, j + 6, k + 1, Blocks.stonebrick, 0);
		worldGen.setBlock(world, i + 1, j + 6, k + 2, Blocks.stonebrick, 0);
		worldGen.setBlock(world, i + 1, j + 6, k + 3, Blocks.stonebrick, 0);
		worldGen.setBlock(world, i + 1, j + 6, k + 4, Blocks.stonebrick, 0);
		worldGen.setBlock(world, i + 1, j + 6, k + 5, Blocks.stonebrick, 0);
		worldGen.setBlock(world, i + 1, j + 6, k + 6, Blocks.stonebrick, 0);
		worldGen.setBlock(world, i + 1, j + 6, k + 7, Blocks.stonebrick, 0);
		worldGen.setBlock(world, i + 1, j + 6, k + 8, Blocks.stonebrick, 0);
		worldGen.setBlock(world, i + 1, j + 6, k + 9, Blocks.stonebrick, 0);
		worldGen.setBlock(world, i + 1, j + 6, k + 10, Blocks.bedrock, 0);
		worldGen.setBlock(world, i + 1, j + 7, k + 0, Blocks.bedrock, 0);
		worldGen.setBlock(world, i + 1, j + 7, k + 1, Blocks.stonebrick, 0);
		worldGen.setBlock(world, i + 1, j + 7, k + 2, Blocks.stonebrick, 0);
		worldGen.setBlock(world, i + 1, j + 7, k + 3, Blocks.stonebrick, 0);
		worldGen.setBlock(world, i + 1, j + 7, k + 4, Blocks.stonebrick, 0);
		worldGen.setBlock(world, i + 1, j + 7, k + 5, Blocks.stonebrick, 0);
		worldGen.setBlock(world, i + 1, j + 7, k + 6, Blocks.stonebrick, 0);
		worldGen.setBlock(world, i + 1, j + 7, k + 7, Blocks.stonebrick, 0);
		worldGen.setBlock(world, i + 1, j + 7, k + 8, Blocks.stonebrick, 0);
		worldGen.setBlock(world, i + 1, j + 7, k + 9, Blocks.stonebrick, 0);
		worldGen.setBlock(world, i + 1, j + 7, k + 10, Blocks.bedrock, 0);
		worldGen.setBlock(world, i + 1, j + 8, k + 0, Blocks.bedrock, 0);
		worldGen.setBlock(world, i + 1, j + 8, k + 1, Blocks.stonebrick, 0);
		worldGen.setBlock(world, i + 1, j + 8, k + 2, Blocks.stonebrick, 0);
		worldGen.setBlock(world, i + 1, j + 8, k + 3, Blocks.stonebrick, 0);
		worldGen.setBlock(world, i + 1, j + 8, k + 4, Blocks.stonebrick, 0);
		worldGen.setBlock(world, i + 1, j + 8, k + 5, Blocks.stonebrick, 0);
		worldGen.setBlock(world, i + 1, j + 8, k + 6, Blocks.stonebrick, 0);
		worldGen.setBlock(world, i + 1, j + 8, k + 7, Blocks.stonebrick, 0);
		worldGen.setBlock(world, i + 1, j + 8, k + 8, Blocks.stonebrick, 0);
		worldGen.setBlock(world, i + 1, j + 8, k + 9, Blocks.stonebrick, 0);
		worldGen.setBlock(world, i + 1, j + 8, k + 10, Blocks.bedrock, 0);
		worldGen.setBlock(world, i + 1, j + 9, k + 0, Blocks.bedrock, 0);
		worldGen.setBlock(world, i + 1, j + 9, k + 1, Blocks.stonebrick, 0);
		worldGen.setBlock(world, i + 1, j + 9, k + 2, Blocks.stonebrick, 0);
		worldGen.setBlock(world, i + 1, j + 9, k + 3, Blocks.stonebrick, 0);
		worldGen.setBlock(world, i + 1, j + 9, k + 4, Blocks.stonebrick, 0);
		worldGen.setBlock(world, i + 1, j + 9, k + 5, Blocks.stonebrick, 0);
		worldGen.setBlock(world, i + 1, j + 9, k + 6, Blocks.stonebrick, 0);
		worldGen.setBlock(world, i + 1, j + 9, k + 7, Blocks.stonebrick, 0);
		worldGen.setBlock(world, i + 1, j + 9, k + 8, Blocks.stonebrick, 0);
		worldGen.setBlock(world, i + 1, j + 9, k + 9, Blocks.stonebrick, 0);
		worldGen.setBlock(world, i + 1, j + 9, k + 10, Blocks.bedrock, 0);
		worldGen.setBlock(world, i + 1, j + 10, k + 0, Blocks.bedrock, 0);
		worldGen.setBlock(world, i + 1, j + 10, k + 1, Blocks.air, 0);
		worldGen.setBlock(world, i + 1, j + 10, k + 2, Blocks.air, 0);
		worldGen.setBlock(world, i + 1, j + 10, k + 3, Blocks.air, 0);
		worldGen.setBlock(world, i + 1, j + 10, k + 4, Blocks.air, 0);
		worldGen.setBlock(world, i + 1, j + 10, k + 5, Blocks.air, 0);
		worldGen.setBlock(world, i + 1, j + 10, k + 6, Blocks.air, 0);
		worldGen.setBlock(world, i + 1, j + 10, k + 7, Blocks.air, 0);
		worldGen.setBlock(world, i + 1, j + 10, k + 8, Blocks.air, 0);
		worldGen.setBlock(world, i + 1, j + 10, k + 9, Blocks.air, 0);
		worldGen.setBlock(world, i + 1, j + 10, k + 10, Blocks.bedrock, 0);
		worldGen.setBlock(world, i + 2, j + 0, k + 0, Blocks.bedrock, 0);
		worldGen.setBlock(world, i + 2, j + 0, k + 1, Blocks.bedrock, 0);
		worldGen.setBlock(world, i + 2, j + 0, k + 2, Blocks.air, 0);
		worldGen.setBlock(world, i + 2, j + 0, k + 3, Blocks.air, 0);
		worldGen.setBlock(world, i + 2, j + 0, k + 4, Blocks.air, 0);
		worldGen.setBlock(world, i + 2, j + 0, k + 5, Blocks.air, 0);
		worldGen.setBlock(world, i + 2, j + 0, k + 6, Blocks.air, 0);
		worldGen.setBlock(world, i + 2, j + 0, k + 7, Blocks.air, 0);
		worldGen.setBlock(world, i + 2, j + 0, k + 8, Blocks.air, 0);
		worldGen.setBlock(world, i + 2, j + 0, k + 9, Blocks.bedrock, 0);
		worldGen.setBlock(world, i + 2, j + 0, k + 10, Blocks.bedrock, 0);
		worldGen.setBlock(world, i + 2, j + 1, k + 0, Blocks.bedrock, 0);
		worldGen.setBlock(world, i + 2, j + 1, k + 1, Blocks.stonebrick, 0);
		worldGen.setBlock(world, i + 2, j + 1, k + 2, Blocks.air, 0);
		worldGen.setBlock(world, i + 2, j + 1, k + 3, Blocks.air, 0);
		worldGen.setBlock(world, i + 2, j + 1, k + 4, Blocks.air, 0);
		worldGen.setBlock(world, i + 2, j + 1, k + 5, Blocks.air, 0);
		worldGen.setBlock(world, i + 2, j + 1, k + 6, Blocks.air, 0);
		worldGen.setBlock(world, i + 2, j + 1, k + 7, Blocks.air, 0);
		worldGen.setBlock(world, i + 2, j + 1, k + 8, Blocks.air, 0);
		worldGen.setBlock(world, i + 2, j + 1, k + 9, Blocks.stonebrick, 0);
		worldGen.setBlock(world, i + 2, j + 1, k + 10, Blocks.bedrock, 0);
		worldGen.setBlock(world, i + 2, j + 2, k + 0, Blocks.bedrock, 0);
		worldGen.setBlock(world, i + 2, j + 2, k + 1, Blocks.stonebrick, 0);
		worldGen.setBlock(world, i + 2, j + 2, k + 2, Blocks.air, 0);
		worldGen.setBlock(world, i + 2, j + 2, k + 3, Blocks.web, 0);
		worldGen.setBlock(world, i + 2, j + 2, k + 4, Blocks.air, 0);
		worldGen.setBlock(world, i + 2, j + 2, k + 5, Blocks.air, 0);
		worldGen.setBlock(world, i + 2, j + 2, k + 6, Blocks.air, 0);
		worldGen.setBlock(world, i + 2, j + 2, k + 7, Blocks.air, 0);
		worldGen.setBlock(world, i + 2, j + 2, k + 8, Blocks.air, 0);
		worldGen.setBlock(world, i + 2, j + 2, k + 9, Blocks.stonebrick, 0);
		worldGen.setBlock(world, i + 2, j + 2, k + 10, Blocks.bedrock, 0);
		worldGen.setBlock(world, i + 2, j + 3, k + 0, Blocks.bedrock, 0);
		worldGen.setBlock(world, i + 2, j + 3, k + 1, Blocks.stonebrick, 0);
		worldGen.setBlock(world, i + 2, j + 3, k + 2, Blocks.air, 0);
		worldGen.setBlock(world, i + 2, j + 3, k + 3, Blocks.air, 0);
		worldGen.setBlock(world, i + 2, j + 3, k + 4, Blocks.air, 0);
		worldGen.setBlock(world, i + 2, j + 3, k + 5, Blocks.air, 0);
		worldGen.setBlock(world, i + 2, j + 3, k + 6, Blocks.air, 0);
		worldGen.setBlock(world, i + 2, j + 3, k + 7, Blocks.air, 0);
		worldGen.setBlock(world, i + 2, j + 3, k + 8, Blocks.air, 0);
		worldGen.setBlock(world, i + 2, j + 3, k + 9, Blocks.stonebrick, 0);
		worldGen.setBlock(world, i + 2, j + 3, k + 10, Blocks.bedrock, 0);
		worldGen.setBlock(world, i + 2, j + 4, k + 0, Blocks.bedrock, 0);
		worldGen.setBlock(world, i + 2, j + 4, k + 1, Blocks.stonebrick, 0);
		worldGen.setBlock(world, i + 2, j + 4, k + 2, Blocks.air, 0);
		worldGen.setBlock(world, i + 2, j + 4, k + 3, Blocks.air, 0);
		worldGen.setBlock(world, i + 2, j + 4, k + 4, Blocks.air, 0);
		worldGen.setBlock(world, i + 2, j + 4, k + 5, Blocks.air, 0);
		worldGen.setBlock(world, i + 2, j + 4, k + 6, Blocks.air, 0);
		worldGen.setBlock(world, i + 2, j + 4, k + 7, Blocks.air, 0);
		worldGen.setBlock(world, i + 2, j + 4, k + 8, Blocks.air, 0);
		worldGen.setBlock(world, i + 2, j + 4, k + 9, Blocks.stonebrick, 0);
		worldGen.setBlock(world, i + 2, j + 4, k + 10, Blocks.bedrock, 0);
		worldGen.setBlock(world, i + 2, j + 5, k + 0, Blocks.bedrock, 0);
		worldGen.setBlock(world, i + 2, j + 5, k + 1, Blocks.stonebrick, 0);
		worldGen.setBlock(world, i + 2, j + 5, k + 2, Blocks.air, 0);
		worldGen.setBlock(world, i + 2, j + 5, k + 3, Blocks.air, 0);
		worldGen.setBlock(world, i + 2, j + 5, k + 4, Blocks.air, 0);
		worldGen.setBlock(world, i + 2, j + 5, k + 5, Blocks.air, 0);
		worldGen.setBlock(world, i + 2, j + 5, k + 6, Blocks.air, 0);
		worldGen.setBlock(world, i + 2, j + 5, k + 7, Blocks.air, 0);
		worldGen.setBlock(world, i + 2, j + 5, k + 8, Blocks.air, 0);
		worldGen.setBlock(world, i + 2, j + 5, k + 9, Blocks.stonebrick, 0);
		worldGen.setBlock(world, i + 2, j + 5, k + 10, Blocks.bedrock, 0);
		worldGen.setBlock(world, i + 2, j + 6, k + 0, Blocks.bedrock, 0);
		worldGen.setBlock(world, i + 2, j + 6, k + 1, Blocks.stonebrick, 0);
		worldGen.setBlock(world, i + 2, j + 6, k + 2, Blocks.air, 0);
		worldGen.setBlock(world, i + 2, j + 6, k + 3, Blocks.air, 0);
		worldGen.setBlock(world, i + 2, j + 6, k + 4, Blocks.air, 0);
		worldGen.setBlock(world, i + 2, j + 6, k + 5, Blocks.air, 0);
		worldGen.setBlock(world, i + 2, j + 6, k + 6, Blocks.air, 0);
		worldGen.setBlock(world, i + 2, j + 6, k + 7, Blocks.air, 0);
		worldGen.setBlock(world, i + 2, j + 6, k + 8, Blocks.air, 0);
		worldGen.setBlock(world, i + 2, j + 6, k + 9, Blocks.stonebrick, 0);
		worldGen.setBlock(world, i + 2, j + 6, k + 10, Blocks.bedrock, 0);
		worldGen.setBlock(world, i + 2, j + 7, k + 0, Blocks.bedrock, 0);
		worldGen.setBlock(world, i + 2, j + 7, k + 1, Blocks.stonebrick, 0);
		worldGen.setBlock(world, i + 2, j + 7, k + 2, Blocks.air, 0);
		worldGen.setBlock(world, i + 2, j + 7, k + 3, Blocks.air, 0);
		worldGen.setBlock(world, i + 2, j + 7, k + 4, Blocks.air, 0);
		worldGen.setBlock(world, i + 2, j + 7, k + 5, Blocks.air, 0);
		worldGen.setBlock(world, i + 2, j + 7, k + 6, Blocks.air, 0);
		worldGen.setBlock(world, i + 2, j + 7, k + 7, Blocks.air, 0);
		worldGen.setBlock(world, i + 2, j + 7, k + 8, Blocks.air, 0);
		worldGen.setBlock(world, i + 2, j + 7, k + 9, Blocks.stonebrick, 0);
		worldGen.setBlock(world, i + 2, j + 7, k + 10, Blocks.bedrock, 0);
		worldGen.setBlock(world, i + 2, j + 8, k + 0, Blocks.bedrock, 0);
		worldGen.setBlock(world, i + 2, j + 8, k + 1, Blocks.stonebrick, 0);
		worldGen.setBlock(world, i + 2, j + 8, k + 2, Blocks.stonebrick, 0);
		worldGen.setBlock(world, i + 2, j + 8, k + 3, Blocks.stonebrick, 0);
		worldGen.setBlock(world, i + 2, j + 8, k + 4, Blocks.stonebrick, 0);
		worldGen.setBlock(world, i + 2, j + 8, k + 5, Blocks.stonebrick, 0);
		worldGen.setBlock(world, i + 2, j + 8, k + 6, Blocks.stonebrick, 0);
		worldGen.setBlock(world, i + 2, j + 8, k + 7, Blocks.stonebrick, 0);
		worldGen.setBlock(world, i + 2, j + 8, k + 8, Blocks.stonebrick, 0);
		worldGen.setBlock(world, i + 2, j + 8, k + 9, Blocks.stonebrick, 0);
		worldGen.setBlock(world, i + 2, j + 8, k + 10, Blocks.bedrock, 0);
		worldGen.setBlock(world, i + 2, j + 9, k + 0, Blocks.bedrock, 0);
		worldGen.setBlock(world, i + 2, j + 9, k + 1, Blocks.stonebrick, 0);
		worldGen.setBlock(world, i + 2, j + 9, k + 2, Blocks.air, 0);
		worldGen.setBlock(world, i + 2, j + 9, k + 3, Blocks.air, 0);
		worldGen.setBlock(world, i + 2, j + 9, k + 4, Blocks.air, 0);
		worldGen.setBlock(world, i + 2, j + 9, k + 5, Blocks.air, 0);
		worldGen.setBlock(world, i + 2, j + 9, k + 6, Blocks.air, 0);
		worldGen.setBlock(world, i + 2, j + 9, k + 7, Blocks.air, 0);
		worldGen.setBlock(world, i + 2, j + 9, k + 8, Blocks.air, 0);
		worldGen.setBlock(world, i + 2, j + 9, k + 9, Blocks.stonebrick, 0);
		worldGen.setBlock(world, i + 2, j + 9, k + 10, Blocks.bedrock, 0);
		worldGen.setBlock(world, i + 2, j + 10, k + 0, Blocks.bedrock, 0);
		worldGen.setBlock(world, i + 2, j + 10, k + 1, Blocks.air, 0);
		worldGen.setBlock(world, i + 2, j + 10, k + 2, Blocks.air, 0);
		worldGen.setBlock(world, i + 2, j + 10, k + 3, Blocks.air, 0);
		worldGen.setBlock(world, i + 2, j + 10, k + 4, Blocks.air, 0);
		worldGen.setBlock(world, i + 2, j + 10, k + 5, Blocks.air, 0);
		worldGen.setBlock(world, i + 2, j + 10, k + 6, Blocks.air, 0);
		worldGen.setBlock(world, i + 2, j + 10, k + 7, Blocks.air, 0);
		worldGen.setBlock(world, i + 2, j + 10, k + 8, Blocks.air, 0);
		worldGen.setBlock(world, i + 2, j + 10, k + 9, Blocks.air, 0);
		worldGen.setBlock(world, i + 2, j + 10, k + 10, Blocks.bedrock, 0);
		worldGen.setBlock(world, i + 3, j + 0, k + 0, Blocks.bedrock, 0);
		worldGen.setBlock(world, i + 3, j + 0, k + 1, Blocks.bedrock, 0);
		worldGen.setBlock(world, i + 3, j + 0, k + 2, Blocks.air, 0);
		worldGen.setBlock(world, i + 3, j + 0, k + 3, Blocks.air, 0);
		worldGen.setBlock(world, i + 3, j + 0, k + 4, Blocks.air, 0);
		worldGen.setBlock(world, i + 3, j + 0, k + 5, Blocks.air, 0);
		worldGen.setBlock(world, i + 3, j + 0, k + 6, Blocks.air, 0);
		worldGen.setBlock(world, i + 3, j + 0, k + 7, Blocks.air, 0);
		worldGen.setBlock(world, i + 3, j + 0, k + 8, Blocks.air, 0);
		worldGen.setBlock(world, i + 3, j + 0, k + 9, Blocks.bedrock, 0);
		worldGen.setBlock(world, i + 3, j + 0, k + 10, Blocks.bedrock, 0);
		worldGen.setBlock(world, i + 3, j + 1, k + 0, Blocks.bedrock, 0);
		worldGen.setBlock(world, i + 3, j + 1, k + 1, Blocks.stonebrick, 0);
		worldGen.setBlock(world, i + 3, j + 1, k + 2, Blocks.air, 0);
		worldGen.setBlock(world, i + 3, j + 1, k + 3, Blocks.air, 0);
		worldGen.setBlock(world, i + 3, j + 1, k + 4, Blocks.air, 0);
		worldGen.setBlock(world, i + 3, j + 1, k + 5, Blocks.air, 0);
		worldGen.setBlock(world, i + 3, j + 1, k + 6, Blocks.air, 0);
		worldGen.setBlock(world, i + 3, j + 1, k + 7, Blocks.air, 0);
		worldGen.setBlock(world, i + 3, j + 1, k + 8, Blocks.air, 0);
		worldGen.setBlock(world, i + 3, j + 1, k + 9, Blocks.stonebrick, 0);
		worldGen.setBlock(world, i + 3, j + 1, k + 10, Blocks.bedrock, 0);
		worldGen.setBlock(world, i + 3, j + 2, k + 0, Blocks.bedrock, 0);
		worldGen.setBlock(world, i + 3, j + 2, k + 1, Blocks.stonebrick, 0);
		worldGen.setBlock(world, i + 3, j + 2, k + 2, Blocks.air, 0);
		worldGen.setBlock(world, i + 3, j + 2, k + 3, Blocks.air, 0);
		worldGen.setBlock(world, i + 3, j + 2, k + 4, Blocks.air, 0);
		worldGen.setBlock(world, i + 3, j + 2, k + 5, Blocks.air, 0);
		worldGen.setBlock(world, i + 3, j + 2, k + 6, Blocks.air, 0);
		worldGen.setBlock(world, i + 3, j + 2, k + 7, Blocks.air, 0);
		worldGen.setBlock(world, i + 3, j + 2, k + 8, Blocks.air, 0);
		worldGen.setBlock(world, i + 3, j + 2, k + 9, Blocks.stonebrick, 0);
		worldGen.setBlock(world, i + 3, j + 2, k + 10, Blocks.bedrock, 0);
		worldGen.setBlock(world, i + 3, j + 3, k + 0, Blocks.bedrock, 0);
		worldGen.setBlock(world, i + 3, j + 3, k + 1, Blocks.stonebrick, 0);
		worldGen.setBlock(world, i + 3, j + 3, k + 2, Blocks.air, 0);
		worldGen.setBlock(world, i + 3, j + 3, k + 3, Blocks.air, 0);
		worldGen.setBlock(world, i + 3, j + 3, k + 4, Blocks.air, 0);
		worldGen.setBlock(world, i + 3, j + 3, k + 5, Blocks.air, 0);
		worldGen.setBlock(world, i + 3, j + 3, k + 6, Blocks.air, 0);
		worldGen.setBlock(world, i + 3, j + 3, k + 7, Blocks.air, 0);
		worldGen.setBlock(world, i + 3, j + 3, k + 8, Blocks.air, 0);
		worldGen.setBlock(world, i + 3, j + 3, k + 9, Blocks.stonebrick, 0);
		worldGen.setBlock(world, i + 3, j + 3, k + 10, Blocks.bedrock, 0);
		worldGen.setBlock(world, i + 3, j + 4, k + 0, Blocks.bedrock, 0);
		worldGen.setBlock(world, i + 3, j + 4, k + 1, Blocks.stonebrick, 0);
		worldGen.setBlock(world, i + 3, j + 4, k + 2, Blocks.air, 0);
		worldGen.setBlock(world, i + 3, j + 4, k + 3, Blocks.air, 0);
		worldGen.setBlock(world, i + 3, j + 4, k + 4, Blocks.air, 0);
		worldGen.setBlock(world, i + 3, j + 4, k + 5, Blocks.air, 0);
		worldGen.setBlock(world, i + 3, j + 4, k + 6, Blocks.air, 0);
		worldGen.setBlock(world, i + 3, j + 4, k + 7, Blocks.air, 0);
		worldGen.setBlock(world, i + 3, j + 4, k + 8, Blocks.air, 0);
		worldGen.setBlock(world, i + 3, j + 4, k + 9, Blocks.stonebrick, 0);
		worldGen.setBlock(world, i + 3, j + 4, k + 10, Blocks.bedrock, 0);
		worldGen.setBlock(world, i + 3, j + 5, k + 0, Blocks.bedrock, 0);
		worldGen.setBlock(world, i + 3, j + 5, k + 1, Blocks.stonebrick, 0);
		worldGen.setBlock(world, i + 3, j + 5, k + 2, Blocks.air, 0);
		worldGen.setBlock(world, i + 3, j + 5, k + 3, Blocks.air, 0);
		worldGen.setBlock(world, i + 3, j + 5, k + 4, Blocks.air, 0);
		worldGen.setBlock(world, i + 3, j + 5, k + 5, Blocks.air, 0);
		worldGen.setBlock(world, i + 3, j + 5, k + 6, Blocks.air, 0);
		worldGen.setBlock(world, i + 3, j + 5, k + 7, Blocks.air, 0);
		worldGen.setBlock(world, i + 3, j + 5, k + 8, Blocks.air, 0);
		worldGen.setBlock(world, i + 3, j + 5, k + 9, Blocks.stonebrick, 0);
		worldGen.setBlock(world, i + 3, j + 5, k + 10, Blocks.bedrock, 0);
		worldGen.setBlock(world, i + 3, j + 6, k + 0, Blocks.bedrock, 0);
		worldGen.setBlock(world, i + 3, j + 6, k + 1, Blocks.stonebrick, 0);
		worldGen.setBlock(world, i + 3, j + 6, k + 2, Blocks.air, 0);
		worldGen.setBlock(world, i + 3, j + 6, k + 3, Blocks.air, 0);
		worldGen.setBlock(world, i + 3, j + 6, k + 4, Blocks.air, 0);
		worldGen.setBlock(world, i + 3, j + 6, k + 5, Blocks.air, 0);
		worldGen.setBlock(world, i + 3, j + 6, k + 6, Blocks.air, 0);
		worldGen.setBlock(world, i + 3, j + 6, k + 7, Blocks.air, 0);
		worldGen.setBlock(world, i + 3, j + 6, k + 8, Blocks.air, 0);
		worldGen.setBlock(world, i + 3, j + 6, k + 9, Blocks.stonebrick, 0);
		worldGen.setBlock(world, i + 3, j + 6, k + 10, Blocks.bedrock, 0);
		worldGen.setBlock(world, i + 3, j + 7, k + 0, Blocks.bedrock, 0);
		worldGen.setBlock(world, i + 3, j + 7, k + 1, Blocks.stonebrick, 0);
		worldGen.setBlock(world, i + 3, j + 7, k + 2, Blocks.air, 0);
		worldGen.setBlock(world, i + 3, j + 7, k + 3, Blocks.stonebrick, 0);
		worldGen.setBlock(world, i + 3, j + 7, k + 4, Blocks.stonebrick, 0);
		worldGen.setBlock(world, i + 3, j + 7, k + 5, Blocks.stonebrick, 0);
		worldGen.setBlock(world, i + 3, j + 7, k + 6, Blocks.stonebrick, 0);
		worldGen.setBlock(world, i + 3, j + 7, k + 7, Blocks.stonebrick, 0);
		worldGen.setBlock(world, i + 3, j + 7, k + 8, Blocks.air, 0);
		worldGen.setBlock(world, i + 3, j + 7, k + 9, Blocks.stonebrick, 0);
		worldGen.setBlock(world, i + 3, j + 7, k + 10, Blocks.bedrock, 0);
		worldGen.setBlock(world, i + 3, j + 8, k + 0, Blocks.bedrock, 0);
		worldGen.setBlock(world, i + 3, j + 8, k + 1, Blocks.stonebrick, 0);
		worldGen.setBlock(world, i + 3, j + 8, k + 2, Blocks.stonebrick, 0);
		worldGen.setBlock(world, i + 3, j + 8, k + 3, Blocks.air, 0);
		worldGen.setBlock(world, i + 3, j + 8, k + 4, Blocks.air, 0);
		worldGen.setBlock(world, i + 3, j + 8, k + 5, Blocks.air, 0);
		worldGen.setBlock(world, i + 3, j + 8, k + 6, Blocks.air, 0);
		worldGen.setBlock(world, i + 3, j + 8, k + 7, Blocks.air, 0);
		worldGen.setBlock(world, i + 3, j + 8, k + 8, Blocks.stonebrick, 0);
		worldGen.setBlock(world, i + 3, j + 8, k + 9, Blocks.stonebrick, 0);
		worldGen.setBlock(world, i + 3, j + 8, k + 10, Blocks.bedrock, 0);
		worldGen.setBlock(world, i + 3, j + 9, k + 0, Blocks.bedrock, 0);
		worldGen.setBlock(world, i + 3, j + 9, k + 1, Blocks.stonebrick, 0);
		worldGen.setBlock(world, i + 3, j + 9, k + 2, Blocks.air, 0);
		worldGen.setBlock(world, i + 3, j + 9, k + 3, Blocks.air, 0);
		worldGen.setBlock(world, i + 3, j + 9, k + 4, Blocks.air, 0);
		worldGen.setBlock(world, i + 3, j + 9, k + 5, Blocks.air, 0);
		worldGen.setBlock(world, i + 3, j + 9, k + 6, Blocks.air, 0);
		worldGen.setBlock(world, i + 3, j + 9, k + 7, Blocks.air, 0);
		worldGen.setBlock(world, i + 3, j + 9, k + 8, Blocks.air, 0);
		worldGen.setBlock(world, i + 3, j + 9, k + 9, Blocks.stonebrick, 0);
		worldGen.setBlock(world, i + 3, j + 9, k + 10, Blocks.bedrock, 0);
		worldGen.setBlock(world, i + 3, j + 10, k + 0, Blocks.bedrock, 0);
		worldGen.setBlock(world, i + 3, j + 10, k + 1, Blocks.air, 0);
		worldGen.setBlock(world, i + 3, j + 10, k + 2, Blocks.air, 0);
		worldGen.setBlock(world, i + 3, j + 10, k + 3, Blocks.air, 0);
		worldGen.setBlock(world, i + 3, j + 10, k + 4, Blocks.air, 0);
		worldGen.setBlock(world, i + 3, j + 10, k + 5, Blocks.air, 0);
		worldGen.setBlock(world, i + 3, j + 10, k + 6, Blocks.air, 0);
		worldGen.setBlock(world, i + 3, j + 10, k + 7, Blocks.air, 0);
		worldGen.setBlock(world, i + 3, j + 10, k + 8, Blocks.air, 0);
		worldGen.setBlock(world, i + 3, j + 10, k + 9, Blocks.air, 0);
		worldGen.setBlock(world, i + 3, j + 10, k + 10, Blocks.bedrock, 0);
		worldGen.setBlock(world, i + 4, j + 0, k + 0, Blocks.bedrock, 0);
		worldGen.setBlock(world, i + 4, j + 0, k + 1, Blocks.bedrock, 0);
		worldGen.setBlock(world, i + 4, j + 0, k + 2, Blocks.air, 0);
		worldGen.setBlock(world, i + 4, j + 0, k + 3, Blocks.air, 0);
		worldGen.setBlock(world, i + 4, j + 0, k + 4, Blocks.air, 0);
		worldGen.setBlock(world, i + 4, j + 0, k + 5, Blocks.air, 0);
		worldGen.setBlock(world, i + 4, j + 0, k + 6, Blocks.air, 0);
		worldGen.setBlock(world, i + 4, j + 0, k + 7, Blocks.air, 0);
		worldGen.setBlock(world, i + 4, j + 0, k + 8, Blocks.air, 0);
		worldGen.setBlock(world, i + 4, j + 0, k + 9, Blocks.bedrock, 0);
		worldGen.setBlock(world, i + 4, j + 0, k + 10, Blocks.bedrock, 0);
		worldGen.setBlock(world, i + 4, j + 1, k + 0, Blocks.bedrock, 0);
		worldGen.setBlock(world, i + 4, j + 1, k + 1, Blocks.stonebrick, 0);
		worldGen.setBlock(world, i + 4, j + 1, k + 2, Blocks.air, 0);
		worldGen.setBlock(world, i + 4, j + 1, k + 3, Blocks.air, 0);
		worldGen.setBlock(world, i + 4, j + 1, k + 4, Blocks.air, 0);
		worldGen.setBlock(world, i + 4, j + 1, k + 5, Blocks.air, 0);
		worldGen.setBlock(world, i + 4, j + 1, k + 6, Blocks.air, 0);
		worldGen.setBlock(world, i + 4, j + 1, k + 7, Blocks.air, 0);
		worldGen.setBlock(world, i + 4, j + 1, k + 8, Blocks.air, 0);
		worldGen.setBlock(world, i + 4, j + 1, k + 9, Blocks.stonebrick, 0);
		worldGen.setBlock(world, i + 4, j + 1, k + 10, Blocks.bedrock, 0);
		worldGen.setBlock(world, i + 4, j + 2, k + 0, Blocks.bedrock, 0);
		worldGen.setBlock(world, i + 4, j + 2, k + 1, Blocks.stonebrick, 0);
		worldGen.setBlock(world, i + 4, j + 2, k + 2, Blocks.air, 0);
		worldGen.setBlock(world, i + 4, j + 2, k + 3, Blocks.air, 0);
		worldGen.setBlock(world, i + 4, j + 2, k + 4, Blocks.air, 0);
		worldGen.setBlock(world, i + 4, j + 2, k + 5, Blocks.air, 0);
		worldGen.setBlock(world, i + 4, j + 2, k + 6, Blocks.air, 0);
		worldGen.setBlock(world, i + 4, j + 2, k + 7, Blocks.air, 0);
		worldGen.setBlock(world, i + 4, j + 2, k + 8, Blocks.air, 0);
		worldGen.setBlock(world, i + 4, j + 2, k + 9, Blocks.stonebrick, 0);
		worldGen.setBlock(world, i + 4, j + 2, k + 10, Blocks.bedrock, 0);
		worldGen.setBlock(world, i + 4, j + 3, k + 0, Blocks.bedrock, 0);
		worldGen.setBlock(world, i + 4, j + 3, k + 1, Blocks.stonebrick, 0);
		worldGen.setBlock(world, i + 4, j + 3, k + 2, Blocks.air, 0);
		worldGen.setBlock(world, i + 4, j + 3, k + 3, Blocks.air, 0);
		worldGen.setBlock(world, i + 4, j + 3, k + 4, Blocks.air, 0);
		worldGen.setBlock(world, i + 4, j + 3, k + 5, Blocks.air, 0);
		worldGen.setBlock(world, i + 4, j + 3, k + 6, Blocks.air, 0);
		worldGen.setBlock(world, i + 4, j + 3, k + 7, Blocks.air, 0);
		worldGen.setBlock(world, i + 4, j + 3, k + 8, Blocks.air, 0);
		worldGen.setBlock(world, i + 4, j + 3, k + 9, Blocks.stonebrick, 0);
		worldGen.setBlock(world, i + 4, j + 3, k + 10, Blocks.bedrock, 0);
		worldGen.setBlock(world, i + 4, j + 4, k + 0, Blocks.bedrock, 0);
		worldGen.setBlock(world, i + 4, j + 4, k + 1, Blocks.stonebrick, 0);
		worldGen.setBlock(world, i + 4, j + 4, k + 2, Blocks.air, 0);
		worldGen.setBlock(world, i + 4, j + 4, k + 3, Blocks.air, 0);
		worldGen.setBlock(world, i + 4, j + 4, k + 4, Blocks.air, 0);
		worldGen.setBlock(world, i + 4, j + 4, k + 5, Blocks.air, 0);
		worldGen.setBlock(world, i + 4, j + 4, k + 6, Blocks.air, 0);
		worldGen.setBlock(world, i + 4, j + 4, k + 7, Blocks.air, 0);
		worldGen.setBlock(world, i + 4, j + 4, k + 8, Blocks.air, 0);
		worldGen.setBlock(world, i + 4, j + 4, k + 9, Blocks.stonebrick, 0);
		worldGen.setBlock(world, i + 4, j + 4, k + 10, Blocks.bedrock, 0);
		worldGen.setBlock(world, i + 4, j + 5, k + 0, Blocks.bedrock, 0);
		worldGen.setBlock(world, i + 4, j + 5, k + 1, Blocks.stonebrick, 0);
		worldGen.setBlock(world, i + 4, j + 5, k + 2, Blocks.air, 0);
		worldGen.setBlock(world, i + 4, j + 5, k + 3, Blocks.air, 0);
		worldGen.setBlock(world, i + 4, j + 5, k + 4, Blocks.air, 0);
		worldGen.setBlock(world, i + 4, j + 5, k + 5, Blocks.air, 0);
		worldGen.setBlock(world, i + 4, j + 5, k + 6, Blocks.air, 0);
		worldGen.setBlock(world, i + 4, j + 5, k + 7, Blocks.air, 0);
		worldGen.setBlock(world, i + 4, j + 5, k + 8, Blocks.air, 0);
		worldGen.setBlock(world, i + 4, j + 5, k + 9, Blocks.stonebrick, 0);
		worldGen.setBlock(world, i + 4, j + 5, k + 10, Blocks.bedrock, 0);
		worldGen.setBlock(world, i + 4, j + 6, k + 0, Blocks.bedrock, 0);
		worldGen.setBlock(world, i + 4, j + 6, k + 1, Blocks.stonebrick, 0);
		worldGen.setBlock(world, i + 4, j + 6, k + 2, Blocks.air, 0);
		worldGen.setBlock(world, i + 4, j + 6, k + 3, Blocks.air, 0);
		worldGen.setBlock(world, i + 4, j + 6, k + 4, Blocks.stonebrick, 0);
		worldGen.setBlock(world, i + 4, j + 6, k + 5, Blocks.stonebrick, 0);
		worldGen.setBlock(world, i + 4, j + 6, k + 6, Blocks.stonebrick, 0);
		worldGen.setBlock(world, i + 4, j + 6, k + 7, Blocks.air, 0);
		worldGen.setBlock(world, i + 4, j + 6, k + 8, Blocks.air, 0);
		worldGen.setBlock(world, i + 4, j + 6, k + 9, Blocks.stonebrick, 0);
		worldGen.setBlock(world, i + 4, j + 6, k + 10, Blocks.bedrock, 0);
		worldGen.setBlock(world, i + 4, j + 7, k + 0, Blocks.bedrock, 0);
		worldGen.setBlock(world, i + 4, j + 7, k + 1, Blocks.stonebrick, 0);
		worldGen.setBlock(world, i + 4, j + 7, k + 2, Blocks.air, 0);
		worldGen.setBlock(world, i + 4, j + 7, k + 3, Blocks.stonebrick, 0);
		worldGen.setBlock(world, i + 4, j + 7, k + 4, Blocks.air, 0);
		worldGen.setBlock(world, i + 4, j + 7, k + 5, Blocks.air, 0);
		worldGen.setBlock(world, i + 4, j + 7, k + 6, Blocks.air, 0);
		worldGen.setBlock(world, i + 4, j + 7, k + 7, Blocks.stonebrick, 0);
		worldGen.setBlock(world, i + 4, j + 7, k + 8, Blocks.air, 0);
		worldGen.setBlock(world, i + 4, j + 7, k + 9, Blocks.stonebrick, 0);
		worldGen.setBlock(world, i + 4, j + 7, k + 10, Blocks.bedrock, 0);
		worldGen.setBlock(world, i + 4, j + 8, k + 0, Blocks.bedrock, 0);
		worldGen.setBlock(world, i + 4, j + 8, k + 1, Blocks.stonebrick, 0);
		worldGen.setBlock(world, i + 4, j + 8, k + 2, Blocks.stonebrick, 0);
		worldGen.setBlock(world, i + 4, j + 8, k + 3, Blocks.air, 0);
		worldGen.setBlock(world, i + 4, j + 8, k + 4, Blocks.air, 0);
		worldGen.setBlock(world, i + 4, j + 8, k + 5, Blocks.air, 0);
		worldGen.setBlock(world, i + 4, j + 8, k + 6, Blocks.air, 0);
		worldGen.setBlock(world, i + 4, j + 8, k + 7, Blocks.air, 0);
		worldGen.setBlock(world, i + 4, j + 8, k + 8, Blocks.stonebrick, 0);
		worldGen.setBlock(world, i + 4, j + 8, k + 9, Blocks.stonebrick, 0);
		worldGen.setBlock(world, i + 4, j + 8, k + 10, Blocks.bedrock, 0);
		worldGen.setBlock(world, i + 4, j + 9, k + 0, Blocks.bedrock, 0);
		worldGen.setBlock(world, i + 4, j + 9, k + 1, Blocks.stonebrick, 0);
		worldGen.setBlock(world, i + 4, j + 9, k + 2, Blocks.air, 0);
		worldGen.setBlock(world, i + 4, j + 9, k + 3, Blocks.air, 0);
		worldGen.setBlock(world, i + 4, j + 9, k + 4, Blocks.air, 0);
		worldGen.setBlock(world, i + 4, j + 9, k + 5, Blocks.air, 0);
		worldGen.setBlock(world, i + 4, j + 9, k + 6, Blocks.air, 0);
		worldGen.setBlock(world, i + 4, j + 9, k + 7, Blocks.air, 0);
		worldGen.setBlock(world, i + 4, j + 9, k + 8, Blocks.air, 0);
		worldGen.setBlock(world, i + 4, j + 9, k + 9, Blocks.stonebrick, 0);
		worldGen.setBlock(world, i + 4, j + 9, k + 10, Blocks.bedrock, 0);
		worldGen.setBlock(world, i + 4, j + 10, k + 0, Blocks.bedrock, 0);
		worldGen.setBlock(world, i + 4, j + 10, k + 1, Blocks.air, 0);
		worldGen.setBlock(world, i + 4, j + 10, k + 2, Blocks.air, 0);
		worldGen.setBlock(world, i + 4, j + 10, k + 3, Blocks.air, 0);
		worldGen.setBlock(world, i + 4, j + 10, k + 4, Blocks.air, 0);
		worldGen.setBlock(world, i + 4, j + 10, k + 5, Blocks.air, 0);
		worldGen.setBlock(world, i + 4, j + 10, k + 6, Blocks.air, 0);
		worldGen.setBlock(world, i + 4, j + 10, k + 7, Blocks.air, 0);
		worldGen.setBlock(world, i + 4, j + 10, k + 8, Blocks.air, 0);
		worldGen.setBlock(world, i + 4, j + 10, k + 9, Blocks.air, 0);
		worldGen.setBlock(world, i + 4, j + 10, k + 10, Blocks.bedrock, 0);
		worldGen.setBlock(world, i + 5, j + 0, k + 0, Blocks.bedrock, 0);
		worldGen.setBlock(world, i + 5, j + 0, k + 1, Blocks.bedrock, 0);
		worldGen.setBlock(world, i + 5, j + 0, k + 2, Blocks.air, 0);
		worldGen.setBlock(world, i + 5, j + 0, k + 3, Blocks.air, 0);
		worldGen.setBlock(world, i + 5, j + 0, k + 4, Blocks.air, 0);
		worldGen.setBlock(world, i + 5, j + 0, k + 5, Blocks.air, 0);
		worldGen.setBlock(world, i + 5, j + 0, k + 6, Blocks.air, 0);
		worldGen.setBlock(world, i + 5, j + 0, k + 7, Blocks.air, 0);
		worldGen.setBlock(world, i + 5, j + 0, k + 8, Blocks.air, 0);
		worldGen.setBlock(world, i + 5, j + 0, k + 9, Blocks.bedrock, 0);
		worldGen.setBlock(world, i + 5, j + 0, k + 10, Blocks.bedrock, 0);
		worldGen.setBlock(world, i + 5, j + 1, k + 0, Blocks.bedrock, 0);
		worldGen.setBlock(world, i + 5, j + 1, k + 1, Blocks.stonebrick, 0);
		worldGen.setBlock(world, i + 5, j + 1, k + 2, Blocks.air, 0);
		worldGen.setBlock(world, i + 5, j + 1, k + 3, Blocks.air, 0);
		worldGen.setBlock(world, i + 5, j + 1, k + 4, Blocks.air, 0);
		worldGen.setBlock(world, i + 5, j + 1, k + 5, Blocks.air, 0);
		worldGen.setBlock(world, i + 5, j + 1, k + 6, Blocks.air, 0);
		worldGen.setBlock(world, i + 5, j + 1, k + 7, Blocks.air, 0);
		worldGen.setBlock(world, i + 5, j + 1, k + 8, Blocks.air, 0);
		worldGen.setBlock(world, i + 5, j + 1, k + 9, Blocks.stonebrick, 0);
		worldGen.setBlock(world, i + 5, j + 1, k + 10, Blocks.bedrock, 0);
		worldGen.setBlock(world, i + 5, j + 2, k + 0, Blocks.bedrock, 0);
		worldGen.setBlock(world, i + 5, j + 2, k + 1, Blocks.stonebrick, 0);
		worldGen.setBlock(world, i + 5, j + 2, k + 2, Blocks.air, 0);
		worldGen.setBlock(world, i + 5, j + 2, k + 3, Blocks.air, 0);
		worldGen.setBlock(world, i + 5, j + 2, k + 4, Blocks.air, 0);
		worldGen.setBlock(world, i + 5, j + 2, k + 5, Blocks.air, 0);
		worldGen.setBlock(world, i + 5, j + 2, k + 6, Blocks.air, 0);
		worldGen.setBlock(world, i + 5, j + 2, k + 7, Blocks.air, 0);
		worldGen.setBlock(world, i + 5, j + 2, k + 8, Blocks.air, 0);
		worldGen.setBlock(world, i + 5, j + 2, k + 9, Blocks.cobblestone, 0);
		worldGen.setBlock(world, i + 5, j + 2, k + 10, Blocks.bedrock, 0);
		worldGen.setBlock(world, i + 5, j + 3, k + 0, Blocks.bedrock, 0);
		worldGen.setBlock(world, i + 5, j + 3, k + 1, Blocks.stonebrick, 0);
		worldGen.setBlock(world, i + 5, j + 3, k + 2, Blocks.air, 0);
		worldGen.setBlock(world, i + 5, j + 3, k + 3, Blocks.air, 0);
		worldGen.setBlock(world, i + 5, j + 3, k + 4, Blocks.air, 0);
		worldGen.setBlock(world, i + 5, j + 3, k + 5, Blocks.air, 0);
		worldGen.setBlock(world, i + 5, j + 3, k + 6, Blocks.air, 0);
		worldGen.setBlock(world, i + 5, j + 3, k + 7, Blocks.air, 0);
		worldGen.setBlock(world, i + 5, j + 3, k + 8, Blocks.air, 0);
		worldGen.setBlock(world, i + 5, j + 3, k + 9, Blocks.stonebrick, 0);
		worldGen.setBlock(world, i + 5, j + 3, k + 10, Blocks.bedrock, 0);
		worldGen.setBlock(world, i + 5, j + 4, k + 0, Blocks.bedrock, 0);
		worldGen.setBlock(world, i + 5, j + 4, k + 1, Blocks.stonebrick, 0);
		worldGen.setBlock(world, i + 5, j + 4, k + 2, Blocks.air, 0);
		worldGen.setBlock(world, i + 5, j + 4, k + 3, Blocks.air, 0);
		worldGen.setBlock(world, i + 5, j + 4, k + 4, Blocks.air, 0);
		worldGen.setBlock(world, i + 5, j + 4, k + 5, Blocks.air, 0);
		worldGen.setBlock(world, i + 5, j + 4, k + 6, Blocks.air, 0);
		worldGen.setBlock(world, i + 5, j + 4, k + 7, Blocks.air, 0);
		worldGen.setBlock(world, i + 5, j + 4, k + 8, Blocks.air, 0);
		worldGen.setBlock(world, i + 5, j + 4, k + 9, Blocks.stonebrick, 0);
		worldGen.setBlock(world, i + 5, j + 4, k + 10, Blocks.bedrock, 0);
		worldGen.setBlock(world, i + 5, j + 5, k + 0, Blocks.bedrock, 0);
		worldGen.setBlock(world, i + 5, j + 5, k + 1, Blocks.stonebrick, 0);
		worldGen.setBlock(world, i + 5, j + 5, k + 2, Blocks.air, 0);
		worldGen.setBlock(world, i + 5, j + 5, k + 3, Blocks.air, 0);
		worldGen.setBlock(world, i + 5, j + 5, k + 4, Blocks.air, 0);
		worldGen.setBlock(world, i + 5, j + 5, k + 5, Blocks.air, 0);
		worldGen.setBlock(world, i + 5, j + 5, k + 6, Blocks.air, 0);
		worldGen.setBlock(world, i + 5, j + 5, k + 7, Blocks.air, 0);
		worldGen.setBlock(world, i + 5, j + 5, k + 8, Blocks.air, 0);
		worldGen.setBlock(world, i + 5, j + 5, k + 9, Blocks.stonebrick, 0);
		worldGen.setBlock(world, i + 5, j + 5, k + 10, Blocks.bedrock, 0);
		worldGen.setBlock(world, i + 5, j + 6, k + 0, Blocks.bedrock, 0);
		worldGen.setBlock(world, i + 5, j + 6, k + 1, Blocks.stonebrick, 0);
		worldGen.setBlock(world, i + 5, j + 6, k + 2, Blocks.air, 0);
		worldGen.setBlock(world, i + 5, j + 6, k + 3, Blocks.air, 0);
		worldGen.setBlock(world, i + 5, j + 6, k + 4, Blocks.stonebrick, 0);
		worldGen.setBlock(world, i + 5, j + 6, k + 5, Blocks.air, 10);
		worldGen.setBlock(world, i + 5, j + 6, k + 6, Blocks.stonebrick, 0);
		worldGen.setBlock(world, i + 5, j + 6, k + 7, Blocks.air, 0);
		worldGen.setBlock(world, i + 5, j + 6, k + 8, Blocks.air, 0);
		worldGen.setBlock(world, i + 5, j + 6, k + 9, Blocks.stonebrick, 0);
		worldGen.setBlock(world, i + 5, j + 6, k + 10, Blocks.bedrock, 0);
		worldGen.setBlock(world, i + 5, j + 7, k + 0, Blocks.bedrock, 0);
		worldGen.setBlock(world, i + 5, j + 7, k + 1, Blocks.stonebrick, 0);
		worldGen.setBlock(world, i + 5, j + 7, k + 2, Blocks.air, 0);
		worldGen.setBlock(world, i + 5, j + 7, k + 3, Blocks.stonebrick, 0);
		worldGen.setBlock(world, i + 5, j + 7, k + 4, Blocks.air, 0);
		worldGen.setBlock(world, i + 5, j + 7, k + 5, Blocks.air, 0);
		worldGen.setBlock(world, i + 5, j + 7, k + 6, Blocks.air, 0);
		worldGen.setBlock(world, i + 5, j + 7, k + 7, Blocks.stonebrick, 0);
		worldGen.setBlock(world, i + 5, j + 7, k + 8, Blocks.air, 0);
		worldGen.setBlock(world, i + 5, j + 7, k + 9, Blocks.stonebrick, 0);
		worldGen.setBlock(world, i + 5, j + 7, k + 10, Blocks.bedrock, 0);
		worldGen.setBlock(world, i + 5, j + 8, k + 0, Blocks.bedrock, 0);
		worldGen.setBlock(world, i + 5, j + 8, k + 1, Blocks.stonebrick, 0);
		worldGen.setBlock(world, i + 5, j + 8, k + 2, Blocks.stonebrick, 0);
		worldGen.setBlock(world, i + 5, j + 8, k + 3, Blocks.air, 0);
		worldGen.setBlock(world, i + 5, j + 8, k + 4, Blocks.air, 0);
		worldGen.setBlock(world, i + 5, j + 8, k + 5, Blocks.air, 0);
		worldGen.setBlock(world, i + 5, j + 8, k + 6, Blocks.air, 0);
		worldGen.setBlock(world, i + 5, j + 8, k + 7, Blocks.air, 0);
		worldGen.setBlock(world, i + 5, j + 8, k + 8, Blocks.stonebrick, 0);
		worldGen.setBlock(world, i + 5, j + 8, k + 9, Blocks.stonebrick, 0);
		worldGen.setBlock(world, i + 5, j + 8, k + 10, Blocks.bedrock, 0);
		worldGen.setBlock(world, i + 5, j + 9, k + 0, Blocks.bedrock, 0);
		worldGen.setBlock(world, i + 5, j + 9, k + 1, Blocks.stonebrick, 0);
		worldGen.setBlock(world, i + 5, j + 9, k + 2, Blocks.air, 0);
		worldGen.setBlock(world, i + 5, j + 9, k + 3, Blocks.air, 0);
		worldGen.setBlock(world, i + 5, j + 9, k + 4, Blocks.air, 0);
		worldGen.setBlock(world, i + 5, j + 9, k + 5, Blocks.air, 0);
		worldGen.setBlock(world, i + 5, j + 9, k + 6, Blocks.air, 0);
		worldGen.setBlock(world, i + 5, j + 9, k + 7, Blocks.air, 0);
		worldGen.setBlock(world, i + 5, j + 9, k + 8, Blocks.air, 0);
		worldGen.setBlock(world, i + 5, j + 9, k + 9, Blocks.stonebrick, 0);
		worldGen.setBlock(world, i + 5, j + 9, k + 10, Blocks.bedrock, 0);
		worldGen.setBlock(world, i + 5, j + 10, k + 0, Blocks.bedrock, 0);
		worldGen.setBlock(world, i + 5, j + 10, k + 1, Blocks.air, 0);
		worldGen.setBlock(world, i + 5, j + 10, k + 2, Blocks.air, 0);
		worldGen.setBlock(world, i + 5, j + 10, k + 3, Blocks.air, 0);
		worldGen.setBlock(world, i + 5, j + 10, k + 4, Blocks.air, 0);
		worldGen.setBlock(world, i + 5, j + 10, k + 5, Blocks.air, 0);
		worldGen.setBlock(world, i + 5, j + 10, k + 6, Blocks.air, 0);
		worldGen.setBlock(world, i + 5, j + 10, k + 7, Blocks.air, 0);
		worldGen.setBlock(world, i + 5, j + 10, k + 8, Blocks.air, 0);
		worldGen.setBlock(world, i + 5, j + 10, k + 9, Blocks.air, 0);
		worldGen.setBlock(world, i + 5, j + 10, k + 10, Blocks.bedrock, 0);
		worldGen.setBlock(world, i + 6, j + 0, k + 0, Blocks.bedrock, 0);
		worldGen.setBlock(world, i + 6, j + 0, k + 1, Blocks.bedrock, 0);
		worldGen.setBlock(world, i + 6, j + 0, k + 2, Blocks.air, 0);
		worldGen.setBlock(world, i + 6, j + 0, k + 3, Blocks.air, 0);
		worldGen.setBlock(world, i + 6, j + 0, k + 4, Blocks.air, 0);
		worldGen.setBlock(world, i + 6, j + 0, k + 5, Blocks.air, 0);
		worldGen.setBlock(world, i + 6, j + 0, k + 6, Blocks.air, 0);
		worldGen.setBlock(world, i + 6, j + 0, k + 7, Blocks.air, 0);
		worldGen.setBlock(world, i + 6, j + 0, k + 8, Blocks.air, 0);
		worldGen.setBlock(world, i + 6, j + 0, k + 9, Blocks.bedrock, 0);
		worldGen.setBlock(world, i + 6, j + 0, k + 10, Blocks.bedrock, 0);
		worldGen.setBlock(world, i + 6, j + 1, k + 0, Blocks.bedrock, 0);
		worldGen.setBlock(world, i + 6, j + 1, k + 1, Blocks.stonebrick, 0);
		worldGen.setBlock(world, i + 6, j + 1, k + 2, Blocks.air, 0);
		worldGen.setBlock(world, i + 6, j + 1, k + 3, Blocks.air, 0);
		worldGen.setBlock(world, i + 6, j + 1, k + 4, Blocks.air, 0);
		worldGen.setBlock(world, i + 6, j + 1, k + 5, Blocks.air, 0);
		worldGen.setBlock(world, i + 6, j + 1, k + 6, Blocks.air, 0);
		worldGen.setBlock(world, i + 6, j + 1, k + 7, Blocks.air, 0);
		worldGen.setBlock(world, i + 6, j + 1, k + 8, Blocks.air, 0);
		worldGen.setBlock(world, i + 6, j + 1, k + 9, Blocks.stonebrick, 0);
		worldGen.setBlock(world, i + 6, j + 1, k + 10, Blocks.bedrock, 0);
		worldGen.setBlock(world, i + 6, j + 2, k + 0, Blocks.bedrock, 0);
		worldGen.setBlock(world, i + 6, j + 2, k + 1, Blocks.stonebrick, 0);
		worldGen.setBlock(world, i + 6, j + 2, k + 2, Blocks.air, 0);
		worldGen.setBlock(world, i + 6, j + 2, k + 3, Blocks.air, 0);
		worldGen.setBlock(world, i + 6, j + 2, k + 4, Blocks.air, 0);
		worldGen.setBlock(world, i + 6, j + 2, k + 5, Blocks.air, 0);
		worldGen.setBlock(world, i + 6, j + 2, k + 6, Blocks.air, 0);
		worldGen.setBlock(world, i + 6, j + 2, k + 7, Blocks.air, 0);
		worldGen.setBlock(world, i + 6, j + 2, k + 8, Blocks.air, 0);
		worldGen.setBlock(world, i + 6, j + 2, k + 9, Blocks.stonebrick, 0);
		worldGen.setBlock(world, i + 6, j + 2, k + 10, Blocks.bedrock, 0);
		worldGen.setBlock(world, i + 6, j + 3, k + 0, Blocks.bedrock, 0);
		worldGen.setBlock(world, i + 6, j + 3, k + 1, Blocks.stonebrick, 0);
		worldGen.setBlock(world, i + 6, j + 3, k + 2, Blocks.air, 0);
		worldGen.setBlock(world, i + 6, j + 3, k + 3, Blocks.air, 0);
		worldGen.setBlock(world, i + 6, j + 3, k + 4, Blocks.air, 0);
		worldGen.setBlock(world, i + 6, j + 3, k + 5, Blocks.air, 0);
		worldGen.setBlock(world, i + 6, j + 3, k + 6, Blocks.air, 0);
		worldGen.setBlock(world, i + 6, j + 3, k + 7, Blocks.air, 0);
		worldGen.setBlock(world, i + 6, j + 3, k + 8, Blocks.air, 0);
		worldGen.setBlock(world, i + 6, j + 3, k + 9, Blocks.cobblestone, 0);
		worldGen.setBlock(world, i + 6, j + 3, k + 10, Blocks.bedrock, 0);
		worldGen.setBlock(world, i + 6, j + 4, k + 0, Blocks.bedrock, 0);
		worldGen.setBlock(world, i + 6, j + 4, k + 1, Blocks.stonebrick, 0);
		worldGen.setBlock(world, i + 6, j + 4, k + 2, Blocks.air, 0);
		worldGen.setBlock(world, i + 6, j + 4, k + 3, Blocks.air, 0);
		worldGen.setBlock(world, i + 6, j + 4, k + 4, Blocks.air, 0);
		worldGen.setBlock(world, i + 6, j + 4, k + 5, Blocks.air, 0);
		worldGen.setBlock(world, i + 6, j + 4, k + 6, Blocks.air, 0);
		worldGen.setBlock(world, i + 6, j + 4, k + 7, Blocks.air, 0);
		worldGen.setBlock(world, i + 6, j + 4, k + 8, Blocks.air, 0);
		worldGen.setBlock(world, i + 6, j + 4, k + 9, Blocks.stonebrick, 0);
		worldGen.setBlock(world, i + 6, j + 4, k + 10, Blocks.bedrock, 0);
		worldGen.setBlock(world, i + 6, j + 5, k + 0, Blocks.bedrock, 0);
		worldGen.setBlock(world, i + 6, j + 5, k + 1, Blocks.stonebrick, 0);
		worldGen.setBlock(world, i + 6, j + 5, k + 2, Blocks.air, 0);
		worldGen.setBlock(world, i + 6, j + 5, k + 3, Blocks.air, 0);
		worldGen.setBlock(world, i + 6, j + 5, k + 4, Blocks.air, 0);
		worldGen.setBlock(world, i + 6, j + 5, k + 5, Blocks.air, 0);
		worldGen.setBlock(world, i + 6, j + 5, k + 6, Blocks.air, 0);
		worldGen.setBlock(world, i + 6, j + 5, k + 7, Blocks.air, 0);
		worldGen.setBlock(world, i + 6, j + 5, k + 8, Blocks.air, 0);
		worldGen.setBlock(world, i + 6, j + 5, k + 9, Blocks.stone_slab, 3);
		worldGen.setBlock(world, i + 6, j + 5, k + 10, Blocks.bedrock, 0);
		worldGen.setBlock(world, i + 6, j + 6, k + 0, Blocks.bedrock, 0);
		worldGen.setBlock(world, i + 6, j + 6, k + 1, Blocks.stonebrick, 0);
		worldGen.setBlock(world, i + 6, j + 6, k + 2, Blocks.air, 0);
		worldGen.setBlock(world, i + 6, j + 6, k + 3, Blocks.air, 0);
		worldGen.setBlock(world, i + 6, j + 6, k + 4, Blocks.stonebrick, 0);
		worldGen.setBlock(world, i + 6, j + 6, k + 5, Blocks.stonebrick, 0);
		worldGen.setBlock(world, i + 6, j + 6, k + 6, Blocks.stonebrick, 0);
		worldGen.setBlock(world, i + 6, j + 6, k + 7, Blocks.air, 0);
		worldGen.setBlock(world, i + 6, j + 6, k + 8, Blocks.air, 0);
		worldGen.setBlock(world, i + 6, j + 6, k + 9, Blocks.stonebrick, 0);
		worldGen.setBlock(world, i + 6, j + 6, k + 10, Blocks.bedrock, 0);
		worldGen.setBlock(world, i + 6, j + 7, k + 0, Blocks.bedrock, 0);
		worldGen.setBlock(world, i + 6, j + 7, k + 1, Blocks.stonebrick, 0);
		worldGen.setBlock(world, i + 6, j + 7, k + 2, Blocks.air, 0);
		worldGen.setBlock(world, i + 6, j + 7, k + 3, Blocks.stonebrick, 0);
		worldGen.setBlock(world, i + 6, j + 7, k + 4, Blocks.air, 0);
		worldGen.setBlock(world, i + 6, j + 7, k + 5, Blocks.air, 0);
		worldGen.setBlock(world, i + 6, j + 7, k + 6, Blocks.air, 0);
		worldGen.setBlock(world, i + 6, j + 7, k + 7, Blocks.stonebrick, 0);
		worldGen.setBlock(world, i + 6, j + 7, k + 8, Blocks.air, 0);
		worldGen.setBlock(world, i + 6, j + 7, k + 9, Blocks.stonebrick, 0);
		worldGen.setBlock(world, i + 6, j + 7, k + 10, Blocks.bedrock, 0);
		worldGen.setBlock(world, i + 6, j + 8, k + 0, Blocks.bedrock, 0);
		worldGen.setBlock(world, i + 6, j + 8, k + 1, Blocks.stonebrick, 0);
		worldGen.setBlock(world, i + 6, j + 8, k + 2, Blocks.stonebrick, 0);
		worldGen.setBlock(world, i + 6, j + 8, k + 3, Blocks.air, 0);
		worldGen.setBlock(world, i + 6, j + 8, k + 4, Blocks.air, 0);
		worldGen.setBlock(world, i + 6, j + 8, k + 5, Blocks.air, 0);
		worldGen.setBlock(world, i + 6, j + 8, k + 6, Blocks.air, 0);
		worldGen.setBlock(world, i + 6, j + 8, k + 7, Blocks.air, 0);
		worldGen.setBlock(world, i + 6, j + 8, k + 8, Blocks.stonebrick, 0);
		worldGen.setBlock(world, i + 6, j + 8, k + 9, Blocks.stonebrick, 0);
		worldGen.setBlock(world, i + 6, j + 8, k + 10, Blocks.bedrock, 0);
		worldGen.setBlock(world, i + 6, j + 9, k + 0, Blocks.bedrock, 0);
		worldGen.setBlock(world, i + 6, j + 9, k + 1, Blocks.stonebrick, 0);
		worldGen.setBlock(world, i + 6, j + 9, k + 2, Blocks.air, 0);
		worldGen.setBlock(world, i + 6, j + 9, k + 3, Blocks.air, 0);
		worldGen.setBlock(world, i + 6, j + 9, k + 4, Blocks.air, 0);
		worldGen.setBlock(world, i + 6, j + 9, k + 5, Blocks.air, 0);
		worldGen.setBlock(world, i + 6, j + 9, k + 6, Blocks.air, 0);
		worldGen.setBlock(world, i + 6, j + 9, k + 7, Blocks.air, 0);
		worldGen.setBlock(world, i + 6, j + 9, k + 8, Blocks.air, 0);
		worldGen.setBlock(world, i + 6, j + 9, k + 9, Blocks.stonebrick, 0);
		worldGen.setBlock(world, i + 6, j + 9, k + 10, Blocks.bedrock, 0);
		worldGen.setBlock(world, i + 6, j + 10, k + 0, Blocks.bedrock, 0);
		worldGen.setBlock(world, i + 6, j + 10, k + 1, Blocks.air, 0);
		worldGen.setBlock(world, i + 6, j + 10, k + 2, Blocks.air, 0);
		worldGen.setBlock(world, i + 6, j + 10, k + 3, Blocks.air, 0);
		worldGen.setBlock(world, i + 6, j + 10, k + 4, Blocks.air, 0);
		worldGen.setBlock(world, i + 6, j + 10, k + 5, Blocks.air, 0);
		worldGen.setBlock(world, i + 6, j + 10, k + 6, Blocks.air, 0);
		worldGen.setBlock(world, i + 6, j + 10, k + 7, Blocks.air, 0);
		worldGen.setBlock(world, i + 6, j + 10, k + 8, Blocks.air, 0);
		worldGen.setBlock(world, i + 6, j + 10, k + 9, Blocks.air, 0);
		worldGen.setBlock(world, i + 6, j + 10, k + 10, Blocks.bedrock, 0);
		worldGen.setBlock(world, i + 7, j + 0, k + 0, Blocks.bedrock, 0);
		worldGen.setBlock(world, i + 7, j + 0, k + 1, Blocks.bedrock, 0);
		worldGen.setBlock(world, i + 7, j + 0, k + 2, Blocks.air, 0);
		worldGen.setBlock(world, i + 7, j + 0, k + 3, Blocks.air, 0);
		worldGen.setBlock(world, i + 7, j + 0, k + 4, Blocks.air, 0);
		worldGen.setBlock(world, i + 7, j + 0, k + 5, Blocks.air, 0);
		worldGen.setBlock(world, i + 7, j + 0, k + 6, Blocks.air, 0);
		worldGen.setBlock(world, i + 7, j + 0, k + 7, Blocks.air, 0);
		worldGen.setBlock(world, i + 7, j + 0, k + 8, Blocks.air, 0);
		worldGen.setBlock(world, i + 7, j + 0, k + 9, Blocks.bedrock, 0);
		worldGen.setBlock(world, i + 7, j + 0, k + 10, Blocks.bedrock, 0);
		worldGen.setBlock(world, i + 7, j + 1, k + 0, Blocks.bedrock, 0);
		worldGen.setBlock(world, i + 7, j + 1, k + 1, Blocks.stonebrick, 0);
		worldGen.setBlock(world, i + 7, j + 1, k + 2, Blocks.air, 0);
		worldGen.setBlock(world, i + 7, j + 1, k + 3, Blocks.air, 0);
		worldGen.setBlock(world, i + 7, j + 1, k + 4, Blocks.air, 0);
		worldGen.setBlock(world, i + 7, j + 1, k + 5, Blocks.air, 0);
		worldGen.setBlock(world, i + 7, j + 1, k + 6, Blocks.air, 0);
		worldGen.setBlock(world, i + 7, j + 1, k + 7, Blocks.air, 0);
		worldGen.setBlock(world, i + 7, j + 1, k + 8, Blocks.air, 0);
		worldGen.setBlock(world, i + 7, j + 1, k + 9, Blocks.stonebrick, 0);
		worldGen.setBlock(world, i + 7, j + 1, k + 10, Blocks.bedrock, 0);
		worldGen.setBlock(world, i + 7, j + 2, k + 0, Blocks.bedrock, 0);
		worldGen.setBlock(world, i + 7, j + 2, k + 1, Blocks.stonebrick, 0);
		worldGen.setBlock(world, i + 7, j + 2, k + 2, Blocks.air, 0);
		worldGen.setBlock(world, i + 7, j + 2, k + 3, Blocks.air, 0);
		worldGen.setBlock(world, i + 7, j + 2, k + 4, Blocks.air, 0);
		worldGen.setBlock(world, i + 7, j + 2, k + 5, Blocks.air, 0);
		worldGen.setBlock(world, i + 7, j + 2, k + 6, Blocks.air, 0);
		worldGen.setBlock(world, i + 7, j + 2, k + 7, Blocks.air, 0);
		worldGen.setBlock(world, i + 7, j + 2, k + 8, Blocks.air, 0);
		worldGen.setBlock(world, i + 7, j + 2, k + 9, Blocks.stonebrick, 0);
		worldGen.setBlock(world, i + 7, j + 2, k + 10, Blocks.bedrock, 0);
		worldGen.setBlock(world, i + 7, j + 3, k + 0, Blocks.bedrock, 0);
		worldGen.setBlock(world, i + 7, j + 3, k + 1, Blocks.stonebrick, 0);
		worldGen.setBlock(world, i + 7, j + 3, k + 2, Blocks.air, 0);
		worldGen.setBlock(world, i + 7, j + 3, k + 3, Blocks.air, 0);
		worldGen.setBlock(world, i + 7, j + 3, k + 4, Blocks.air, 0);
		worldGen.setBlock(world, i + 7, j + 3, k + 5, Blocks.air, 0);
		worldGen.setBlock(world, i + 7, j + 3, k + 6, Blocks.air, 0);
		worldGen.setBlock(world, i + 7, j + 3, k + 7, Blocks.air, 0);
		worldGen.setBlock(world, i + 7, j + 3, k + 8, Blocks.air, 0);
		worldGen.setBlock(world, i + 7, j + 3, k + 9, Blocks.stonebrick, 0);
		worldGen.setBlock(world, i + 7, j + 3, k + 10, Blocks.bedrock, 0);
		worldGen.setBlock(world, i + 7, j + 4, k + 0, Blocks.bedrock, 0);
		worldGen.setBlock(world, i + 7, j + 4, k + 1, Blocks.stonebrick, 0);
		worldGen.setBlock(world, i + 7, j + 4, k + 2, Blocks.air, 0);
		worldGen.setBlock(world, i + 7, j + 4, k + 3, Blocks.air, 0);
		worldGen.setBlock(world, i + 7, j + 4, k + 4, Blocks.air, 0);
		worldGen.setBlock(world, i + 7, j + 4, k + 5, Blocks.air, 0);
		worldGen.setBlock(world, i + 7, j + 4, k + 6, Blocks.air, 0);
		worldGen.setBlock(world, i + 7, j + 4, k + 7, Blocks.air, 0);
		worldGen.setBlock(world, i + 7, j + 4, k + 8, Blocks.air, 0);
		worldGen.setBlock(world, i + 7, j + 4, k + 9, Blocks.stonebrick, 0);
		worldGen.setBlock(world, i + 7, j + 4, k + 10, Blocks.bedrock, 0);
		worldGen.setBlock(world, i + 7, j + 5, k + 0, Blocks.bedrock, 0);
		worldGen.setBlock(world, i + 7, j + 5, k + 1, Blocks.stonebrick, 0);
		worldGen.setBlock(world, i + 7, j + 5, k + 2, Blocks.air, 0);
		worldGen.setBlock(world, i + 7, j + 5, k + 3, Blocks.air, 0);
		worldGen.setBlock(world, i + 7, j + 5, k + 4, Blocks.air, 0);
		worldGen.setBlock(world, i + 7, j + 5, k + 5, Blocks.air, 0);
		worldGen.setBlock(world, i + 7, j + 5, k + 6, Blocks.air, 0);
		worldGen.setBlock(world, i + 7, j + 5, k + 7, Blocks.air, 0);
		worldGen.setBlock(world, i + 7, j + 5, k + 8, Blocks.air, 0);
		worldGen.setBlock(world, i + 7, j + 5, k + 9, Blocks.stonebrick, 0);
		worldGen.setBlock(world, i + 7, j + 5, k + 10, Blocks.bedrock, 0);
		worldGen.setBlock(world, i + 7, j + 6, k + 0, Blocks.bedrock, 0);
		worldGen.setBlock(world, i + 7, j + 6, k + 1, Blocks.stonebrick, 0);
		worldGen.setBlock(world, i + 7, j + 6, k + 2, Blocks.air, 0);
		worldGen.setBlock(world, i + 7, j + 6, k + 3, Blocks.air, 0);
		worldGen.setBlock(world, i + 7, j + 6, k + 4, Blocks.air, 0);
		worldGen.setBlock(world, i + 7, j + 6, k + 5, Blocks.air, 0);
		worldGen.setBlock(world, i + 7, j + 6, k + 6, Blocks.air, 0);
		worldGen.setBlock(world, i + 7, j + 6, k + 7, Blocks.air, 0);
		worldGen.setBlock(world, i + 7, j + 6, k + 8, Blocks.air, 0);
		worldGen.setBlock(world, i + 7, j + 6, k + 9, Blocks.stonebrick, 0);
		worldGen.setBlock(world, i + 7, j + 6, k + 10, Blocks.bedrock, 0);
		worldGen.setBlock(world, i + 7, j + 7, k + 0, Blocks.bedrock, 0);
		worldGen.setBlock(world, i + 7, j + 7, k + 1, Blocks.stonebrick, 0);
		worldGen.setBlock(world, i + 7, j + 7, k + 2, Blocks.air, 0);
		worldGen.setBlock(world, i + 7, j + 7, k + 3, Blocks.stonebrick, 0);
		worldGen.setBlock(world, i + 7, j + 7, k + 4, Blocks.stonebrick, 0);
		worldGen.setBlock(world, i + 7, j + 7, k + 5, Blocks.stonebrick, 0);
		worldGen.setBlock(world, i + 7, j + 7, k + 6, Blocks.stonebrick, 0);
		worldGen.setBlock(world, i + 7, j + 7, k + 7, Blocks.stonebrick, 0);
		worldGen.setBlock(world, i + 7, j + 7, k + 8, Blocks.air, 0);
		worldGen.setBlock(world, i + 7, j + 7, k + 9, Blocks.stonebrick, 0);
		worldGen.setBlock(world, i + 7, j + 7, k + 10, Blocks.bedrock, 0);
		worldGen.setBlock(world, i + 7, j + 8, k + 0, Blocks.bedrock, 0);
		worldGen.setBlock(world, i + 7, j + 8, k + 1, Blocks.stonebrick, 0);
		worldGen.setBlock(world, i + 7, j + 8, k + 2, Blocks.stonebrick, 0);
		worldGen.setBlock(world, i + 7, j + 8, k + 3, Blocks.air, 0);
		worldGen.setBlock(world, i + 7, j + 8, k + 4, Blocks.air, 0);
		worldGen.setBlock(world, i + 7, j + 8, k + 5, Blocks.air, 0);
		worldGen.setBlock(world, i + 7, j + 8, k + 6, Blocks.air, 0);
		worldGen.setBlock(world, i + 7, j + 8, k + 7, Blocks.air, 0);
		worldGen.setBlock(world, i + 7, j + 8, k + 8, Blocks.stonebrick, 0);
		worldGen.setBlock(world, i + 7, j + 8, k + 9, Blocks.stonebrick, 0);
		worldGen.setBlock(world, i + 7, j + 8, k + 10, Blocks.bedrock, 0);
		worldGen.setBlock(world, i + 7, j + 9, k + 0, Blocks.bedrock, 0);
		worldGen.setBlock(world, i + 7, j + 9, k + 1, Blocks.stonebrick, 0);
		worldGen.setBlock(world, i + 7, j + 9, k + 2, Blocks.air, 0);
		worldGen.setBlock(world, i + 7, j + 9, k + 3, Blocks.air, 0);
		worldGen.setBlock(world, i + 7, j + 9, k + 4, Blocks.air, 0);
		worldGen.setBlock(world, i + 7, j + 9, k + 5, Blocks.air, 0);
		worldGen.setBlock(world, i + 7, j + 9, k + 6, Blocks.air, 0);
		worldGen.setBlock(world, i + 7, j + 9, k + 7, Blocks.air, 0);
		worldGen.setBlock(world, i + 7, j + 9, k + 8, Blocks.air, 0);
		worldGen.setBlock(world, i + 7, j + 9, k + 9, Blocks.stonebrick, 0);
		worldGen.setBlock(world, i + 7, j + 9, k + 10, Blocks.bedrock, 0);
		worldGen.setBlock(world, i + 7, j + 10, k + 0, Blocks.bedrock, 0);
		worldGen.setBlock(world, i + 7, j + 10, k + 1, Blocks.air, 0);
		worldGen.setBlock(world, i + 7, j + 10, k + 2, Blocks.air, 0);
		worldGen.setBlock(world, i + 7, j + 10, k + 3, Blocks.air, 0);
		worldGen.setBlock(world, i + 7, j + 10, k + 4, Blocks.air, 0);
		worldGen.setBlock(world, i + 7, j + 10, k + 5, Blocks.air, 0);
		worldGen.setBlock(world, i + 7, j + 10, k + 6, Blocks.air, 0);
		worldGen.setBlock(world, i + 7, j + 10, k + 7, Blocks.air, 0);
		worldGen.setBlock(world, i + 7, j + 10, k + 8, Blocks.air, 0);
		worldGen.setBlock(world, i + 7, j + 10, k + 9, Blocks.air, 0);
		worldGen.setBlock(world, i + 7, j + 10, k + 10, Blocks.bedrock, 0);
		worldGen.setBlock(world, i + 8, j + 0, k + 0, Blocks.bedrock, 0);
		worldGen.setBlock(world, i + 8, j + 0, k + 1, Blocks.bedrock, 0);
		worldGen.setBlock(world, i + 8, j + 0, k + 2, Blocks.air, 0);
		worldGen.setBlock(world, i + 8, j + 0, k + 3, Blocks.air, 0);
		worldGen.setBlock(world, i + 8, j + 0, k + 4, Blocks.air, 0);
		worldGen.setBlock(world, i + 8, j + 0, k + 5, Blocks.air, 0);
		worldGen.setBlock(world, i + 8, j + 0, k + 6, Blocks.air, 0);
		worldGen.setBlock(world, i + 8, j + 0, k + 7, Blocks.air, 0);
		worldGen.setBlock(world, i + 8, j + 0, k + 8, Blocks.air, 0);
		worldGen.setBlock(world, i + 8, j + 0, k + 9, Blocks.bedrock, 0);
		worldGen.setBlock(world, i + 8, j + 0, k + 10, Blocks.bedrock, 0);
		worldGen.setBlock(world, i + 8, j + 1, k + 0, Blocks.bedrock, 0);
		worldGen.setBlock(world, i + 8, j + 1, k + 1, Blocks.stonebrick, 0);
		worldGen.setBlock(world, i + 8, j + 1, k + 2, Blocks.air, 0);
		worldGen.setBlock(world, i + 8, j + 1, k + 3, Blocks.air, 0);
		worldGen.setBlock(world, i + 8, j + 1, k + 4, Blocks.air, 0);
		worldGen.setBlock(world, i + 8, j + 1, k + 5, Blocks.air, 0);
		worldGen.setBlock(world, i + 8, j + 1, k + 6, Blocks.air, 0);
		worldGen.setBlock(world, i + 8, j + 1, k + 7, Blocks.air, 0);
		worldGen.setBlock(world, i + 8, j + 1, k + 8, Blocks.air, 0);
		worldGen.setBlock(world, i + 8, j + 1, k + 9, Blocks.stonebrick, 0);
		worldGen.setBlock(world, i + 8, j + 1, k + 10, Blocks.bedrock, 0);
		worldGen.setBlock(world, i + 8, j + 2, k + 0, Blocks.bedrock, 0);
		worldGen.setBlock(world, i + 8, j + 2, k + 1, Blocks.cobblestone, 0);
		worldGen.setBlock(world, i + 8, j + 2, k + 2, Blocks.web, 0);
		worldGen.setBlock(world, i + 8, j + 2, k + 3, Blocks.air, 0);
		worldGen.setBlock(world, i + 8, j + 2, k + 4, Blocks.air, 0);
		worldGen.setBlock(world, i + 8, j + 2, k + 5, Blocks.air, 0);
		worldGen.setBlock(world, i + 8, j + 2, k + 6, Blocks.air, 0);
		worldGen.setBlock(world, i + 8, j + 2, k + 7, Blocks.air, 0);
		worldGen.setBlock(world, i + 8, j + 2, k + 8, Blocks.air, 0);
		worldGen.setBlock(world, i + 8, j + 2, k + 9, Blocks.stonebrick, 0);
		worldGen.setBlock(world, i + 8, j + 2, k + 10, Blocks.bedrock, 0);
		worldGen.setBlock(world, i + 8, j + 3, k + 0, Blocks.bedrock, 0);
		worldGen.setBlock(world, i + 8, j + 3, k + 1, Blocks.stonebrick, 0);
		worldGen.setBlock(world, i + 8, j + 3, k + 2, Blocks.air, 0);
		worldGen.setBlock(world, i + 8, j + 3, k + 3, Blocks.air, 0);
		worldGen.setBlock(world, i + 8, j + 3, k + 4, Blocks.air, 0);
		worldGen.setBlock(world, i + 8, j + 3, k + 5, Blocks.air, 0);
		worldGen.setBlock(world, i + 8, j + 3, k + 6, Blocks.air, 0);
		worldGen.setBlock(world, i + 8, j + 3, k + 7, Blocks.air, 0);
		worldGen.setBlock(world, i + 8, j + 3, k + 8, Blocks.air, 0);
		worldGen.setBlock(world, i + 8, j + 3, k + 9, Blocks.stonebrick, 0);
		worldGen.setBlock(world, i + 8, j + 3, k + 10, Blocks.bedrock, 0);
		worldGen.setBlock(world, i + 8, j + 4, k + 0, Blocks.bedrock, 0);
		worldGen.setBlock(world, i + 8, j + 4, k + 1, Blocks.stonebrick, 0);
		worldGen.setBlock(world, i + 8, j + 4, k + 2, Blocks.air, 0);
		worldGen.setBlock(world, i + 8, j + 4, k + 3, Blocks.air, 0);
		worldGen.setBlock(world, i + 8, j + 4, k + 4, Blocks.air, 0);
		worldGen.setBlock(world, i + 8, j + 4, k + 5, Blocks.air, 0);
		worldGen.setBlock(world, i + 8, j + 4, k + 6, Blocks.air, 0);
		worldGen.setBlock(world, i + 8, j + 4, k + 7, Blocks.air, 0);
		worldGen.setBlock(world, i + 8, j + 4, k + 8, Blocks.air, 0);
		worldGen.setBlock(world, i + 8, j + 4, k + 9, Blocks.stonebrick, 0);
		worldGen.setBlock(world, i + 8, j + 4, k + 10, Blocks.bedrock, 0);
		worldGen.setBlock(world, i + 8, j + 5, k + 0, Blocks.bedrock, 0);
		worldGen.setBlock(world, i + 8, j + 5, k + 1, Blocks.stonebrick, 0);
		worldGen.setBlock(world, i + 8, j + 5, k + 2, Blocks.air, 0);
		worldGen.setBlock(world, i + 8, j + 5, k + 3, Blocks.air, 0);
		worldGen.setBlock(world, i + 8, j + 5, k + 4, Blocks.air, 0);
		worldGen.setBlock(world, i + 8, j + 5, k + 5, Blocks.air, 0);
		worldGen.setBlock(world, i + 8, j + 5, k + 6, Blocks.air, 0);
		worldGen.setBlock(world, i + 8, j + 5, k + 7, Blocks.air, 0);
		worldGen.setBlock(world, i + 8, j + 5, k + 8, Blocks.air, 0);
		worldGen.setBlock(world, i + 8, j + 5, k + 9, Blocks.cobblestone, 0);
		worldGen.setBlock(world, i + 8, j + 5, k + 10, Blocks.bedrock, 0);
		worldGen.setBlock(world, i + 8, j + 6, k + 0, Blocks.bedrock, 0);
		worldGen.setBlock(world, i + 8, j + 6, k + 1, Blocks.stonebrick, 0);
		worldGen.setBlock(world, i + 8, j + 6, k + 2, Blocks.air, 0);
		worldGen.setBlock(world, i + 8, j + 6, k + 3, Blocks.air, 0);
		worldGen.setBlock(world, i + 8, j + 6, k + 4, Blocks.air, 0);
		worldGen.setBlock(world, i + 8, j + 6, k + 5, Blocks.air, 0);
		worldGen.setBlock(world, i + 8, j + 6, k + 6, Blocks.air, 0);
		worldGen.setBlock(world, i + 8, j + 6, k + 7, Blocks.air, 0);
		worldGen.setBlock(world, i + 8, j + 6, k + 8, Blocks.air, 0);
		worldGen.setBlock(world, i + 8, j + 6, k + 9, Blocks.stonebrick, 0);
		worldGen.setBlock(world, i + 8, j + 6, k + 10, Blocks.bedrock, 0);
		worldGen.setBlock(world, i + 8, j + 7, k + 0, Blocks.bedrock, 0);
		worldGen.setBlock(world, i + 8, j + 7, k + 1, Blocks.stonebrick, 0);
		worldGen.setBlock(world, i + 8, j + 7, k + 2, Blocks.web, 0);
		worldGen.setBlock(world, i + 8, j + 7, k + 3, Blocks.air, 0);
		worldGen.setBlock(world, i + 8, j + 7, k + 4, Blocks.air, 0);
		worldGen.setBlock(world, i + 8, j + 7, k + 5, Blocks.air, 0);
		worldGen.setBlock(world, i + 8, j + 7, k + 6, Blocks.air, 0);
		worldGen.setBlock(world, i + 8, j + 7, k + 7, Blocks.air, 0);
		worldGen.setBlock(world, i + 8, j + 7, k + 8, Blocks.air, 0);
		worldGen.setBlock(world, i + 8, j + 7, k + 9, Blocks.double_stone_slab, 3);
		worldGen.setBlock(world, i + 8, j + 7, k + 10, Blocks.bedrock, 0);
		worldGen.setBlock(world, i + 8, j + 8, k + 0, Blocks.bedrock, 0);
		worldGen.setBlock(world, i + 8, j + 8, k + 1, Blocks.stonebrick, 0);
		worldGen.setBlock(world, i + 8, j + 8, k + 2, Blocks.stonebrick, 0);
		worldGen.setBlock(world, i + 8, j + 8, k + 3, Blocks.stonebrick, 0);
		worldGen.setBlock(world, i + 8, j + 8, k + 4, Blocks.stonebrick, 0);
		worldGen.setBlock(world, i + 8, j + 8, k + 5, Blocks.stonebrick, 0);
		worldGen.setBlock(world, i + 8, j + 8, k + 6, Blocks.stonebrick, 0);
		worldGen.setBlock(world, i + 8, j + 8, k + 7, Blocks.stonebrick, 0);
		worldGen.setBlock(world, i + 8, j + 8, k + 8, Blocks.stonebrick, 0);
		worldGen.setBlock(world, i + 8, j + 8, k + 9, Blocks.stonebrick, 0);
		worldGen.setBlock(world, i + 8, j + 8, k + 10, Blocks.bedrock, 0);
		worldGen.setBlock(world, i + 8, j + 9, k + 0, Blocks.bedrock, 0);
		worldGen.setBlock(world, i + 8, j + 9, k + 1, Blocks.stonebrick, 0);
		worldGen.setBlock(world, i + 8, j + 9, k + 2, Blocks.air, 0);
		worldGen.setBlock(world, i + 8, j + 9, k + 3, Blocks.air, 0);
		worldGen.setBlock(world, i + 8, j + 9, k + 4, Blocks.air, 0);
		worldGen.setBlock(world, i + 8, j + 9, k + 5, Blocks.air, 0);
		worldGen.setBlock(world, i + 8, j + 9, k + 6, Blocks.air, 0);
		worldGen.setBlock(world, i + 8, j + 9, k + 7, Blocks.air, 0);
		worldGen.setBlock(world, i + 8, j + 9, k + 8, Blocks.air, 0);
		worldGen.setBlock(world, i + 8, j + 9, k + 9, Blocks.stonebrick, 0);
		worldGen.setBlock(world, i + 8, j + 9, k + 10, Blocks.bedrock, 0);
		worldGen.setBlock(world, i + 8, j + 10, k + 0, Blocks.bedrock, 0);
		worldGen.setBlock(world, i + 8, j + 10, k + 1, Blocks.air, 0);
		worldGen.setBlock(world, i + 8, j + 10, k + 2, Blocks.air, 0);
		worldGen.setBlock(world, i + 8, j + 10, k + 3, Blocks.air, 0);
		worldGen.setBlock(world, i + 8, j + 10, k + 4, Blocks.air, 0);
		worldGen.setBlock(world, i + 8, j + 10, k + 5, Blocks.air, 0);
		worldGen.setBlock(world, i + 8, j + 10, k + 6, Blocks.air, 0);
		worldGen.setBlock(world, i + 8, j + 10, k + 7, Blocks.air, 0);
		worldGen.setBlock(world, i + 8, j + 10, k + 8, Blocks.air, 0);
		worldGen.setBlock(world, i + 8, j + 10, k + 9, Blocks.air, 0);
		worldGen.setBlock(world, i + 8, j + 10, k + 10, Blocks.bedrock, 0);
		worldGen.setBlock(world, i + 9, j + 0, k + 0, Blocks.bedrock, 0);
		worldGen.setBlock(world, i + 9, j + 0, k + 1, Blocks.bedrock, 0);
		worldGen.setBlock(world, i + 9, j + 0, k + 2, Blocks.bedrock, 0);
		worldGen.setBlock(world, i + 9, j + 0, k + 3, Blocks.bedrock, 0);
		worldGen.setBlock(world, i + 9, j + 0, k + 4, Blocks.bedrock, 0);
		worldGen.setBlock(world, i + 9, j + 0, k + 5, Blocks.bedrock, 0);
		worldGen.setBlock(world, i + 9, j + 0, k + 6, Blocks.bedrock, 0);
		worldGen.setBlock(world, i + 9, j + 0, k + 7, Blocks.bedrock, 0);
		worldGen.setBlock(world, i + 9, j + 0, k + 8, Blocks.bedrock, 0);
		worldGen.setBlock(world, i + 9, j + 0, k + 9, Blocks.bedrock, 0);
		worldGen.setBlock(world, i + 9, j + 0, k + 10, Blocks.bedrock, 0);
		worldGen.setBlock(world, i + 9, j + 1, k + 0, Blocks.bedrock, 0);
		worldGen.setBlock(world, i + 9, j + 1, k + 1, Blocks.stonebrick, 0);
		worldGen.setBlock(world, i + 9, j + 1, k + 2, Blocks.stonebrick, 0);
		worldGen.setBlock(world, i + 9, j + 1, k + 3, Blocks.stonebrick, 0);
		worldGen.setBlock(world, i + 9, j + 1, k + 4, Blocks.stonebrick, 0);
		worldGen.setBlock(world, i + 9, j + 1, k + 5, Blocks.stonebrick, 0);
		worldGen.setBlock(world, i + 9, j + 1, k + 6, Blocks.stonebrick, 0);
		worldGen.setBlock(world, i + 9, j + 1, k + 7, Blocks.stonebrick, 0);
		worldGen.setBlock(world, i + 9, j + 1, k + 8, Blocks.stonebrick, 0);
		worldGen.setBlock(world, i + 9, j + 1, k + 9, Blocks.stonebrick, 0);
		worldGen.setBlock(world, i + 9, j + 1, k + 10, Blocks.bedrock, 0);
		worldGen.setBlock(world, i + 9, j + 2, k + 0, Blocks.bedrock, 0);
		worldGen.setBlock(world, i + 9, j + 2, k + 1, Blocks.stonebrick, 0);
		worldGen.setBlock(world, i + 9, j + 2, k + 2, Blocks.stonebrick, 0);
		worldGen.setBlock(world, i + 9, j + 2, k + 3, Blocks.stonebrick, 0);
		worldGen.setBlock(world, i + 9, j + 2, k + 4, Blocks.stonebrick, 0);
		worldGen.setBlock(world, i + 9, j + 2, k + 5, Blocks.stonebrick, 0);
		worldGen.setBlock(world, i + 9, j + 2, k + 6, Blocks.stonebrick, 0);
		worldGen.setBlock(world, i + 9, j + 2, k + 7, Blocks.stonebrick, 0);
		worldGen.setBlock(world, i + 9, j + 2, k + 8, Blocks.stonebrick, 0);
		worldGen.setBlock(world, i + 9, j + 2, k + 9, Blocks.stonebrick, 0);
		worldGen.setBlock(world, i + 9, j + 2, k + 10, Blocks.bedrock, 0);
		worldGen.setBlock(world, i + 9, j + 3, k + 0, Blocks.bedrock, 0);
		worldGen.setBlock(world, i + 9, j + 3, k + 1, Blocks.stonebrick, 0);
		worldGen.setBlock(world, i + 9, j + 3, k + 2, Blocks.stonebrick, 0);
		worldGen.setBlock(world, i + 9, j + 3, k + 3, Blocks.stonebrick, 0);
		worldGen.setBlock(world, i + 9, j + 3, k + 4, Blocks.stonebrick, 0);
		worldGen.setBlock(world, i + 9, j + 3, k + 5, Blocks.cobblestone, 0);
		worldGen.setBlock(world, i + 9, j + 3, k + 6, Blocks.stonebrick, 0);
		worldGen.setBlock(world, i + 9, j + 3, k + 7, Blocks.stonebrick, 0);
		worldGen.setBlock(world, i + 9, j + 3, k + 8, Blocks.stonebrick, 0);
		worldGen.setBlock(world, i + 9, j + 3, k + 9, Blocks.stonebrick, 0);
		worldGen.setBlock(world, i + 9, j + 3, k + 10, Blocks.bedrock, 0);
		worldGen.setBlock(world, i + 9, j + 4, k + 0, Blocks.bedrock, 0);
		worldGen.setBlock(world, i + 9, j + 4, k + 1, Blocks.stonebrick, 0);
		worldGen.setBlock(world, i + 9, j + 4, k + 2, Blocks.stonebrick, 0);
		worldGen.setBlock(world, i + 9, j + 4, k + 3, Blocks.stonebrick, 0);
		worldGen.setBlock(world, i + 9, j + 4, k + 4, Blocks.cobblestone, 0);
		worldGen.setBlock(world, i + 9, j + 4, k + 5, Blocks.stonebrick, 0);
		worldGen.setBlock(world, i + 9, j + 4, k + 6, Blocks.stonebrick, 0);
		worldGen.setBlock(world, i + 9, j + 4, k + 7, Blocks.stonebrick, 0);
		worldGen.setBlock(world, i + 9, j + 4, k + 8, Blocks.stonebrick, 0);
		worldGen.setBlock(world, i + 9, j + 4, k + 9, Blocks.stonebrick, 0);
		worldGen.setBlock(world, i + 9, j + 4, k + 10, Blocks.bedrock, 0);
		worldGen.setBlock(world, i + 9, j + 5, k + 0, Blocks.bedrock, 0);
		worldGen.setBlock(world, i + 9, j + 5, k + 1, Blocks.stonebrick, 0);
		worldGen.setBlock(world, i + 9, j + 5, k + 2, Blocks.stonebrick, 0);
		worldGen.setBlock(world, i + 9, j + 5, k + 3, Blocks.stonebrick, 0);
		worldGen.setBlock(world, i + 9, j + 5, k + 4, Blocks.cobblestone, 0);
		worldGen.setBlock(world, i + 9, j + 5, k + 5, Blocks.stonebrick, 0);
		worldGen.setBlock(world, i + 9, j + 5, k + 6, Blocks.cobblestone, 0);
		worldGen.setBlock(world, i + 9, j + 5, k + 7, Blocks.stonebrick, 0);
		worldGen.setBlock(world, i + 9, j + 5, k + 8, Blocks.stonebrick, 0);
		worldGen.setBlock(world, i + 9, j + 5, k + 9, Blocks.stonebrick, 0);
		worldGen.setBlock(world, i + 9, j + 5, k + 10, Blocks.bedrock, 0);
		worldGen.setBlock(world, i + 9, j + 6, k + 0, Blocks.bedrock, 0);
		worldGen.setBlock(world, i + 9, j + 6, k + 1, Blocks.stonebrick, 0);
		worldGen.setBlock(world, i + 9, j + 6, k + 2, Blocks.stonebrick, 0);
		worldGen.setBlock(world, i + 9, j + 6, k + 3, Blocks.stonebrick, 0);
		worldGen.setBlock(world, i + 9, j + 6, k + 4, Blocks.stonebrick, 0);
		worldGen.setBlock(world, i + 9, j + 6, k + 5, Blocks.stonebrick, 0);
		worldGen.setBlock(world, i + 9, j + 6, k + 6, Blocks.stonebrick, 0);
		worldGen.setBlock(world, i + 9, j + 6, k + 7, Blocks.stone_slab, 3);
		worldGen.setBlock(world, i + 9, j + 6, k + 8, Blocks.stonebrick, 0);
		worldGen.setBlock(world, i + 9, j + 6, k + 9, Blocks.stonebrick, 0);
		worldGen.setBlock(world, i + 9, j + 6, k + 10, Blocks.bedrock, 0);
		worldGen.setBlock(world, i + 9, j + 7, k + 0, Blocks.bedrock, 0);
		worldGen.setBlock(world, i + 9, j + 7, k + 1, Blocks.stonebrick, 0);
		worldGen.setBlock(world, i + 9, j + 7, k + 2, Blocks.stonebrick, 0);
		worldGen.setBlock(world, i + 9, j + 7, k + 3, Blocks.stonebrick, 0);
		worldGen.setBlock(world, i + 9, j + 7, k + 4, Blocks.stonebrick, 0);
		worldGen.setBlock(world, i + 9, j + 7, k + 5, Blocks.stonebrick, 0);
		worldGen.setBlock(world, i + 9, j + 7, k + 6, Blocks.stonebrick, 0);
		worldGen.setBlock(world, i + 9, j + 7, k + 7, Blocks.stonebrick, 0);
		worldGen.setBlock(world, i + 9, j + 7, k + 8, Blocks.stonebrick, 0);
		worldGen.setBlock(world, i + 9, j + 7, k + 9, Blocks.stonebrick, 0);
		worldGen.setBlock(world, i + 9, j + 7, k + 10, Blocks.bedrock, 0);
		worldGen.setBlock(world, i + 9, j + 8, k + 0, Blocks.bedrock, 0);
		worldGen.setBlock(world, i + 9, j + 8, k + 1, Blocks.stonebrick, 0);
		worldGen.setBlock(world, i + 9, j + 8, k + 2, Blocks.stonebrick, 0);
		worldGen.setBlock(world, i + 9, j + 8, k + 3, Blocks.stonebrick, 0);
		worldGen.setBlock(world, i + 9, j + 8, k + 4, Blocks.stonebrick, 0);
		worldGen.setBlock(world, i + 9, j + 8, k + 5, Blocks.stonebrick, 0);
		worldGen.setBlock(world, i + 9, j + 8, k + 6, Blocks.stonebrick, 0);
		worldGen.setBlock(world, i + 9, j + 8, k + 7, Blocks.stonebrick, 0);
		worldGen.setBlock(world, i + 9, j + 8, k + 8, Blocks.stonebrick, 0);
		worldGen.setBlock(world, i + 9, j + 8, k + 9, Blocks.stonebrick, 0);
		worldGen.setBlock(world, i + 9, j + 8, k + 10, Blocks.bedrock, 0);
		worldGen.setBlock(world, i + 9, j + 9, k + 0, Blocks.bedrock, 0);
		worldGen.setBlock(world, i + 9, j + 9, k + 1, Blocks.stonebrick, 0);
		worldGen.setBlock(world, i + 9, j + 9, k + 2, Blocks.stonebrick, 0);
		worldGen.setBlock(world, i + 9, j + 9, k + 3, Blocks.stonebrick, 0);
		worldGen.setBlock(world, i + 9, j + 9, k + 4, Blocks.stonebrick, 0);
		worldGen.setBlock(world, i + 9, j + 9, k + 5, Blocks.stonebrick, 0);
		worldGen.setBlock(world, i + 9, j + 9, k + 6, Blocks.stonebrick, 0);
		worldGen.setBlock(world, i + 9, j + 9, k + 7, Blocks.stonebrick, 0);
		worldGen.setBlock(world, i + 9, j + 9, k + 8, Blocks.stonebrick, 0);
		worldGen.setBlock(world, i + 9, j + 9, k + 9, Blocks.stonebrick, 0);
		worldGen.setBlock(world, i + 9, j + 9, k + 10, Blocks.bedrock, 0);
		worldGen.setBlock(world, i + 9, j + 10, k + 0, Blocks.bedrock, 0);
		worldGen.setBlock(world, i + 9, j + 10, k + 1, Blocks.air, 0);
		worldGen.setBlock(world, i + 9, j + 10, k + 2, Blocks.air, 0);
		worldGen.setBlock(world, i + 9, j + 10, k + 3, Blocks.air, 0);
		worldGen.setBlock(world, i + 9, j + 10, k + 4, Blocks.air, 0);
		worldGen.setBlock(world, i + 9, j + 10, k + 5, Blocks.air, 0);
		worldGen.setBlock(world, i + 9, j + 10, k + 6, Blocks.air, 0);
		worldGen.setBlock(world, i + 9, j + 10, k + 7, Blocks.air, 0);
		worldGen.setBlock(world, i + 9, j + 10, k + 8, Blocks.air, 0);
		worldGen.setBlock(world, i + 9, j + 10, k + 9, Blocks.air, 0);
		worldGen.setBlock(world, i + 9, j + 10, k + 10, Blocks.bedrock, 0);
		worldGen.setBlock(world, i + 10, j + 0, k + 0, Blocks.bedrock, 0);
		worldGen.setBlock(world, i + 10, j + 0, k + 1, Blocks.bedrock, 0);
		worldGen.setBlock(world, i + 10, j + 0, k + 2, Blocks.bedrock, 0);
		worldGen.setBlock(world, i + 10, j + 0, k + 3, Blocks.bedrock, 0);
		worldGen.setBlock(world, i + 10, j + 0, k + 4, Blocks.bedrock, 0);
		worldGen.setBlock(world, i + 10, j + 0, k + 5, Blocks.bedrock, 0);
		worldGen.setBlock(world, i + 10, j + 0, k + 6, Blocks.bedrock, 0);
		worldGen.setBlock(world, i + 10, j + 0, k + 7, Blocks.bedrock, 0);
		worldGen.setBlock(world, i + 10, j + 0, k + 8, Blocks.bedrock, 0);
		worldGen.setBlock(world, i + 10, j + 0, k + 9, Blocks.bedrock, 0);
		worldGen.setBlock(world, i + 10, j + 0, k + 10, Blocks.bedrock, 0);
		worldGen.setBlock(world, i + 10, j + 1, k + 0, Blocks.bedrock, 0);
		worldGen.setBlock(world, i + 10, j + 1, k + 1, Blocks.bedrock, 0);
		worldGen.setBlock(world, i + 10, j + 1, k + 2, Blocks.bedrock, 0);
		worldGen.setBlock(world, i + 10, j + 1, k + 3, Blocks.bedrock, 0);
		worldGen.setBlock(world, i + 10, j + 1, k + 4, Blocks.bedrock, 0);
		worldGen.setBlock(world, i + 10, j + 1, k + 5, Blocks.bedrock, 0);
		worldGen.setBlock(world, i + 10, j + 1, k + 6, Blocks.bedrock, 0);
		worldGen.setBlock(world, i + 10, j + 1, k + 7, Blocks.bedrock, 0);
		worldGen.setBlock(world, i + 10, j + 1, k + 8, Blocks.bedrock, 0);
		worldGen.setBlock(world, i + 10, j + 1, k + 9, Blocks.bedrock, 0);
		worldGen.setBlock(world, i + 10, j + 1, k + 10, Blocks.bedrock, 0);
		worldGen.setBlock(world, i + 10, j + 2, k + 0, Blocks.bedrock, 0);
		worldGen.setBlock(world, i + 10, j + 2, k + 1, Blocks.bedrock, 0);
		worldGen.setBlock(world, i + 10, j + 2, k + 2, Blocks.bedrock, 0);
		worldGen.setBlock(world, i + 10, j + 2, k + 3, Blocks.bedrock, 0);
		worldGen.setBlock(world, i + 10, j + 2, k + 4, Blocks.bedrock, 0);
		worldGen.setBlock(world, i + 10, j + 2, k + 5, Blocks.bedrock, 0);
		worldGen.setBlock(world, i + 10, j + 2, k + 6, Blocks.bedrock, 0);
		worldGen.setBlock(world, i + 10, j + 2, k + 7, Blocks.bedrock, 0);
		worldGen.setBlock(world, i + 10, j + 2, k + 8, Blocks.bedrock, 0);
		worldGen.setBlock(world, i + 10, j + 2, k + 9, Blocks.bedrock, 0);
		worldGen.setBlock(world, i + 10, j + 2, k + 10, Blocks.bedrock, 0);
		worldGen.setBlock(world, i + 10, j + 3, k + 0, Blocks.bedrock, 0);
		worldGen.setBlock(world, i + 10, j + 3, k + 1, Blocks.bedrock, 0);
		worldGen.setBlock(world, i + 10, j + 3, k + 2, Blocks.bedrock, 0);
		worldGen.setBlock(world, i + 10, j + 3, k + 3, Blocks.bedrock, 0);
		worldGen.setBlock(world, i + 10, j + 3, k + 4, Blocks.bedrock, 0);
		worldGen.setBlock(world, i + 10, j + 3, k + 5, Blocks.bedrock, 0);
		worldGen.setBlock(world, i + 10, j + 3, k + 6, Blocks.bedrock, 0);
		worldGen.setBlock(world, i + 10, j + 3, k + 7, Blocks.bedrock, 0);
		worldGen.setBlock(world, i + 10, j + 3, k + 8, Blocks.bedrock, 0);
		worldGen.setBlock(world, i + 10, j + 3, k + 9, Blocks.bedrock, 0);
		worldGen.setBlock(world, i + 10, j + 3, k + 10, Blocks.bedrock, 0);
		worldGen.setBlock(world, i + 10, j + 4, k + 0, Blocks.bedrock, 0);
		worldGen.setBlock(world, i + 10, j + 4, k + 1, Blocks.bedrock, 0);
		worldGen.setBlock(world, i + 10, j + 4, k + 2, Blocks.bedrock, 0);
		worldGen.setBlock(world, i + 10, j + 4, k + 3, Blocks.bedrock, 0);
		worldGen.setBlock(world, i + 10, j + 4, k + 4, Blocks.bedrock, 0);
		worldGen.setBlock(world, i + 10, j + 4, k + 5, Blocks.bedrock, 0);
		worldGen.setBlock(world, i + 10, j + 4, k + 6, Blocks.bedrock, 0);
		worldGen.setBlock(world, i + 10, j + 4, k + 7, Blocks.bedrock, 0);
		worldGen.setBlock(world, i + 10, j + 4, k + 8, Blocks.bedrock, 0);
		worldGen.setBlock(world, i + 10, j + 4, k + 9, Blocks.bedrock, 0);
		worldGen.setBlock(world, i + 10, j + 4, k + 10, Blocks.bedrock, 0);
		worldGen.setBlock(world, i + 10, j + 5, k + 0, Blocks.bedrock, 0);
		worldGen.setBlock(world, i + 10, j + 5, k + 1, Blocks.bedrock, 0);
		worldGen.setBlock(world, i + 10, j + 5, k + 2, Blocks.bedrock, 0);
		worldGen.setBlock(world, i + 10, j + 5, k + 3, Blocks.bedrock, 0);
		worldGen.setBlock(world, i + 10, j + 5, k + 4, Blocks.bedrock, 0);
		worldGen.setBlock(world, i + 10, j + 5, k + 5, Blocks.bedrock, 0);
		worldGen.setBlock(world, i + 10, j + 5, k + 6, Blocks.bedrock, 0);
		worldGen.setBlock(world, i + 10, j + 5, k + 7, Blocks.bedrock, 0);
		worldGen.setBlock(world, i + 10, j + 5, k + 8, Blocks.bedrock, 0);
		worldGen.setBlock(world, i + 10, j + 5, k + 9, Blocks.bedrock, 0);
		worldGen.setBlock(world, i + 10, j + 5, k + 10, Blocks.bedrock, 0);
		worldGen.setBlock(world, i + 10, j + 6, k + 0, Blocks.bedrock, 0);
		worldGen.setBlock(world, i + 10, j + 6, k + 1, Blocks.bedrock, 0);
		worldGen.setBlock(world, i + 10, j + 6, k + 2, Blocks.bedrock, 0);
		worldGen.setBlock(world, i + 10, j + 6, k + 3, Blocks.bedrock, 0);
		worldGen.setBlock(world, i + 10, j + 6, k + 4, Blocks.bedrock, 0);
		worldGen.setBlock(world, i + 10, j + 6, k + 5, Blocks.bedrock, 0);
		worldGen.setBlock(world, i + 10, j + 6, k + 6, Blocks.bedrock, 0);
		worldGen.setBlock(world, i + 10, j + 6, k + 7, Blocks.bedrock, 0);
		worldGen.setBlock(world, i + 10, j + 6, k + 8, Blocks.bedrock, 0);
		worldGen.setBlock(world, i + 10, j + 6, k + 9, Blocks.bedrock, 0);
		worldGen.setBlock(world, i + 10, j + 6, k + 10, Blocks.bedrock, 0);
		worldGen.setBlock(world, i + 10, j + 7, k + 0, Blocks.bedrock, 0);
		worldGen.setBlock(world, i + 10, j + 7, k + 1, Blocks.bedrock, 0);
		worldGen.setBlock(world, i + 10, j + 7, k + 2, Blocks.bedrock, 0);
		worldGen.setBlock(world, i + 10, j + 7, k + 3, Blocks.bedrock, 0);
		worldGen.setBlock(world, i + 10, j + 7, k + 4, Blocks.bedrock, 0);
		worldGen.setBlock(world, i + 10, j + 7, k + 5, Blocks.bedrock, 0);
		worldGen.setBlock(world, i + 10, j + 7, k + 6, Blocks.bedrock, 0);
		worldGen.setBlock(world, i + 10, j + 7, k + 7, Blocks.bedrock, 0);
		worldGen.setBlock(world, i + 10, j + 7, k + 8, Blocks.bedrock, 0);
		worldGen.setBlock(world, i + 10, j + 7, k + 9, Blocks.bedrock, 0);
		worldGen.setBlock(world, i + 10, j + 7, k + 10, Blocks.bedrock, 0);
		worldGen.setBlock(world, i + 10, j + 8, k + 0, Blocks.bedrock, 0);
		worldGen.setBlock(world, i + 10, j + 8, k + 1, Blocks.bedrock, 0);
		worldGen.setBlock(world, i + 10, j + 8, k + 2, Blocks.bedrock, 0);
		worldGen.setBlock(world, i + 10, j + 8, k + 3, Blocks.bedrock, 0);
		worldGen.setBlock(world, i + 10, j + 8, k + 4, Blocks.bedrock, 0);
		worldGen.setBlock(world, i + 10, j + 8, k + 5, Blocks.bedrock, 0);
		worldGen.setBlock(world, i + 10, j + 8, k + 6, Blocks.bedrock, 0);
		worldGen.setBlock(world, i + 10, j + 8, k + 7, Blocks.bedrock, 0);
		worldGen.setBlock(world, i + 10, j + 8, k + 8, Blocks.bedrock, 0);
		worldGen.setBlock(world, i + 10, j + 8, k + 9, Blocks.bedrock, 0);
		worldGen.setBlock(world, i + 10, j + 8, k + 10, Blocks.bedrock, 0);
		worldGen.setBlock(world, i + 10, j + 9, k + 0, Blocks.bedrock, 0);
		worldGen.setBlock(world, i + 10, j + 9, k + 1, Blocks.bedrock, 0);
		worldGen.setBlock(world, i + 10, j + 9, k + 2, Blocks.bedrock, 0);
		worldGen.setBlock(world, i + 10, j + 9, k + 3, Blocks.bedrock, 0);
		worldGen.setBlock(world, i + 10, j + 9, k + 4, Blocks.bedrock, 0);
		worldGen.setBlock(world, i + 10, j + 9, k + 5, Blocks.bedrock, 0);
		worldGen.setBlock(world, i + 10, j + 9, k + 6, Blocks.bedrock, 0);
		worldGen.setBlock(world, i + 10, j + 9, k + 7, Blocks.bedrock, 0);
		worldGen.setBlock(world, i + 10, j + 9, k + 8, Blocks.bedrock, 0);
		worldGen.setBlock(world, i + 10, j + 9, k + 9, Blocks.bedrock, 0);
		worldGen.setBlock(world, i + 10, j + 9, k + 10, Blocks.bedrock, 0);
		worldGen.setBlock(world, i + 10, j + 10, k + 0, Blocks.bedrock, 0);
		worldGen.setBlock(world, i + 10, j + 10, k + 1, Blocks.bedrock, 0);
		worldGen.setBlock(world, i + 10, j + 10, k + 2, Blocks.bedrock, 0);
		worldGen.setBlock(world, i + 10, j + 10, k + 3, Blocks.bedrock, 0);
		worldGen.setBlock(world, i + 10, j + 10, k + 4, Blocks.bedrock, 0);
		worldGen.setBlock(world, i + 10, j + 10, k + 5, Blocks.bedrock, 0);
		worldGen.setBlock(world, i + 10, j + 10, k + 6, Blocks.bedrock, 0);
		worldGen.setBlock(world, i + 10, j + 10, k + 7, Blocks.bedrock, 0);
		worldGen.setBlock(world, i + 10, j + 10, k + 8, Blocks.bedrock, 0);
		worldGen.setBlock(world, i + 10, j + 10, k + 9, Blocks.bedrock, 0);
		worldGen.setBlock(world, i + 10, j + 10, k + 10, Blocks.bedrock, 0);
		
	}
	private static int findY(int x, int z,World world) {
		for(int y = 60;y<100;y++){
			BlockPos pos = new BlockPos(x, y, z);
			Block block = world.getBlockState(pos).getBlock();
			if(block.equals(Blocks.grass)){
				return y+1;
			}
			 
		}
		return 0;
	}

}